Workbook

Sheet Vessel Ullage
G2: MARINE SURVEYORS & CONSULTANTS
G3: Av. Almirante Cochrane, 203 sl 81 - Santos /BR
G4: surveyors@naabsa.com | Naabsa.com | TEL: 55 13 3394-0655
A6: VESSEL´S SOUNDING/ULLAGE REPORT
A8: Name of Vessel: | C8: Densa Pelican | G8: Grade of Fuel Ordered: | I8: VLSFO
G9: Location of Survey: | I9: Santos Port - LOCAL
A10: Name of Barges : | C10: XXXXXXXXXXXX | G10: Date of Survey: | I10: January 00th, 2023
G11: Time: | I11: 00:00 x 00:00 h/LT
A17: BEFORE BUNKERING
A18: Draft Fore: | B18: 0 | C18: m | D18: Draft Aft: | E18: 0 | F18: m | G18: List: | H18: 0 | I18: Trim Correction Applied: | K18: Yes | L18: METRIC TONS
A19: Tank nº | B19: Grade | C19: Sounding/ Ullage (m) | D19: Deg °C | E19: Total Vol Observed (m3) | F19: Free Water | H19: Gross Obs Vol (m3) | I19: VCF TAB 54B | J19: Density (S.G.) at 15° C | K19: Gross Std Vol @15° C | L19: IN VAC | M19: IN AIR
F20: Dip | G20: Vol
A21: HFO 1P | B21: VLSFO | C21: 0 | D21: 24 | E21: 0.2 | F21: Nil | G21: 0 | H21: =IF(E21="","",E21-G21) -> 0.2 | I21: =IF(E21="","",S21) -> 0.9938 | J21: 0.9862 | K21: =IF(E21="","",H21*I21) -> 0.19876 | L21: =IF(A21="","",ROUND(SUM(K21*J21),3)) -> 0.196 | M21: =(J21-0.0011)*K21 -> 0.19579848 | N21: =D21-15 -> 9 | O21: =J21*1000 -> 986.2 | P21: =IF(J21>0.8385,186.9696,IF(J21>0.7875,594.5418,IF(J21>0.77,2680.3206,346.4228))) -> 186.9696 | Q21: =IF(J21>0.8385,0.4862,IF(J21>0.7875,0,IF(J21>0.77,-0.00336312,0.4388))) -> 0.4862 | R21: =IF(OR(J21>0.7876,J21=0.7876),(P21/O21^2)+(Q21/O21),IF(OR(J21>0.7701,J21=0.7701),(P21/O21^2)+Q21,(P21/O21^2)+(Q21/O21))) -> 0.00068524223 | S21: =ROUND(EXP(-R21*N21*(1+0.8*R21*N21)),4) -> 0.9938
A22: HFO 1S | B22: VLSFO | C22: 0 | D22: 24 | E22: 134.37 | F22: Nil | G22: 0 | H22: =IF(E22="","",E22-G22) -> 134.37 | I22: =IF(E22="","",S22) -> 0.9938 | J22: 0.9862 | K22: =IF(E22="","",H22*I22) -> 133.53691 | L22: =IF(A22="","",ROUND(SUM(K22*J22),3)) -> 131.694 | M22: =(J22-0.0011)*K22 -> 131.54721 | N22: =D22-15 -> 9 | O22: =J22*1000 -> 986.2 | P22: =IF(J22>0.8385,186.9696,IF(J22>0.7875,594.5418,IF(J22>0.77,2680.3206,346.4228))) -> 186.9696 | Q22: =IF(J22>0.8385,0.4862,IF(J22>0.7875,0,IF(J22>0.77,-0.00336312,0.4388))) -> 0.4862 | R22: =IF(OR(J22>0.7876,J22=0.7876),(P22/O22^2)+(Q22/O22),IF(OR(J22>0.7701,J22=0.7701),(P22/O22^2)+Q22,(P22/O22^2)+(Q22/O22))) -> 0.00068524223 | S22: =ROUND(EXP(-R22*N22*(1+0.8*R22*N22)),4) -> 0.9938
A23: HFO 2P | B23: VLSFO | C23: 0 | D23: 24 | E23: 0.1 | F23: Nil | G23: 0 | H23: =IF(E23="","",E23-G23) -> 0.1 | I23: =IF(E23="","",S23) -> 0.9938 | J23: 0.9896 | K23: =IF(E23="","",H23*I23) -> 0.09938 | L23: =IF(A23="","",ROUND(SUM(K23*J23),3)) -> 0.098 | M23: =(J23-0.0011)*K23 -> 0.09823713 | N23: =D23-15 -> 9 | O23: =J23*1000 -> 989.6 | P23: =IF(J23>0.8385,186.9696,IF(J23>0.7875,594.5418,IF(J23>0.77,2680.3206,346.4228))) -> 186.9696 | Q23: =IF(J23>0.8385,0.4862,IF(J23>0.7875,0,IF(J23>0.77,-0.00336312,0.4388))) -> 0.4862 | R23: =IF(OR(J23>0.7876,J23=0.7876),(P23/O23^2)+(Q23/O23),IF(OR(J23>0.7701,J23=0.7701),(P23/O23^2)+Q23,(P23/O23^2)+(Q23/O23))) -> 0.00068222971 | S23: =ROUND(EXP(-R23*N23*(1+0.8*R23*N23)),4) -> 0.9938
A24: HFO 2S | B24: VLSFO | C24: 0 | D24: 24 | E24: 0.1 | F24: Nil | G24: 0 | H24: =IF(E24="","",E24-G24) -> 0.1 | I24: =IF(E24="","",S24) -> 0.9938 | J24: 0.9896 | K24: =IF(E24="","",H24*I24) -> 0.09938 | L24: =IF(A24="","",ROUND(SUM(K24*J24),3)) -> 0.098 | M24: =(J24-0.0011)*K24 -> 0.09823713 | N24: =D24-15 -> 9 | O24: =J24*1000 -> 989.6 | P24: =IF(J24>0.8385,186.9696,IF(J24>0.7875,594.5418,IF(J24>0.77,2680.3206,346.4228))) -> 186.9696 | Q24: =IF(J24>0.8385,0.4862,IF(J24>0.7875,0,IF(J24>0.77,-0.00336312,0.4388))) -> 0.4862 | R24: =IF(OR(J24>0.7876,J24=0.7876),(P24/O24^2)+(Q24/O24),IF(OR(J24>0.7701,J24=0.7701),(P24/O24^2)+Q24,(P24/O24^2)+(Q24/O24))) -> 0.00068222971 | S24: =ROUND(EXP(-R24*N24*(1+0.8*R24*N24)),4) -> 0.9938
A25: HFO 3P | B25: VLSFO | C25: 0 | D25: 24 | E25: 385.35 | F25: Nil | G25: 0 | H25: =IF(E25="","",E25-G25) -> 385.35 | I25: =IF(E25="","",S25) -> 0.9938 | J25: 0.9862 | K25: =IF(E25="","",H25*I25) -> 382.96083 | L25: =IF(A25="","",ROUND(SUM(K25*J25),3)) -> 377.676 | M25: =(J25-0.0011)*K25 -> 377.25471 | N25: =D25-15 -> 9 | O25: =J25*1000 -> 986.2 | P25: =IF(J25>0.8385,186.9696,IF(J25>0.7875,594.5418,IF(J25>0.77,2680.3206,346.4228))) -> 186.9696 | Q25: =IF(J25>0.8385,0.4862,IF(J25>0.7875,0,IF(J25>0.77,-0.00336312,0.4388))) -> 0.4862 | R25: =IF(OR(J25>0.7876,J25=0.7876),(P25/O25^2)+(Q25/O25),IF(OR(J25>0.7701,J25=0.7701),(P25/O25^2)+Q25,(P25/O25^2)+(Q25/O25))) -> 0.00068524223 | S25: =ROUND(EXP(-R25*N25*(1+0.8*R25*N25)),4) -> 0.9938
A26: HFO 3S | B26: VLSFO | C26: 0 | D26: 24 | E26: 92.39 | F26: Nil | G26: 0 | H26: =IF(E26="","",E26-G26) -> 92.39 | I26: =IF(E26="","",S26) -> 0.9938 | J26: 0.9862 | K26: =IF(E26="","",H26*I26) -> 91.817182 | L26: =IF(A26="","",ROUND(SUM(K26*J26),3)) -> 90.55 | M26: =(J26-0.0011)*K26 -> 90.449106 | N26: =D26-15 -> 9 | O26: =J26*1000 -> 986.2 | P26: =IF(J26>0.8385,186.9696,IF(J26>0.7875,594.5418,IF(J26>0.77,2680.3206,346.4228))) -> 186.9696 | Q26: =IF(J26>0.8385,0.4862,IF(J26>0.7875,0,IF(J26>0.77,-0.00336312,0.4388))) -> 0.4862 | R26: =IF(OR(J26>0.7876,J26=0.7876),(P26/O26^2)+(Q26/O26),IF(OR(J26>0.7701,J26=0.7701),(P26/O26^2)+Q26,(P26/O26^2)+(Q26/O26))) -> 0.00068524223 | S26: =ROUND(EXP(-R26*N26*(1+0.8*R26*N26)),4) -> 0.9938
A27: HFO SERV 1 | B27: VLSFO | C27: GAUGE | D27: 75 | E27: 27 | F27: Nil | G27: 0 | H27: =IF(E27="","",E27-G27) -> 27 | I27: =IF(E27="","",S27) -> 0.9584 | J27: 0.9862 | K27: =IF(E27="","",H27*I27) -> 25.8768 | L27: =IF(A27="","",ROUND(SUM(K27*J27),3)) -> 25.52 | M27: =(J27-0.0011)*K27 -> 25.491236 | N27: =D27-15 -> 60 | O27: =J27*1000 -> 986.2 | P27: =IF(J27>0.8385,186.9696,IF(J27>0.7875,594.5418,IF(J27>0.77,2680.3206,346.4228))) -> 186.9696 | Q27: =IF(J27>0.8385,0.4862,IF(J27>0.7875,0,IF(J27>0.77,-0.00336312,0.4388))) -> 0.4862 | R27: =IF(OR(J27>0.7876,J27=0.7876),(P27/O27^2)+(Q27/O27),IF(OR(J27>0.7701,J27=0.7701),(P27/O27^2)+Q27,(P27/O27^2)+(Q27/O27))) -> 0.00068524223 | S27: =ROUND(EXP(-R27*N27*(1+0.8*R27*N27)),4) -> 0.9584
A28: HFO SETT 1 | B28: VLSFO | C28: GAUGE | D28: 75 | E28: 24 | F28: Nil | G28: 0 | H28: =IF(E28="","",E28-G28) -> 24 | I28: =IF(E28="","",S28) -> 0.9584 | J28: 0.9862 | K28: =IF(E28="","",H28*I28) -> 23.0016 | L28: =IF(A28="","",ROUND(SUM(K28*J28),3)) -> 22.684 | M28: =(J28-0.0011)*K28 -> 22.658876 | N28: =D28-15 -> 60 | O28: =J28*1000 -> 986.2 | P28: =IF(J28>0.8385,186.9696,IF(J28>0.7875,594.5418,IF(J28>0.77,2680.3206,346.4228))) -> 186.9696 | Q28: =IF(J28>0.8385,0.4862,IF(J28>0.7875,0,IF(J28>0.77,-0.00336312,0.4388))) -> 0.4862 | R28: =IF(OR(J28>0.7876,J28=0.7876),(P28/O28^2)+(Q28/O28),IF(OR(J28>0.7701,J28=0.7701),(P28/O28^2)+Q28,(P28/O28^2)+(Q28/O28))) -> 0.00068524223 | S28: =ROUND(EXP(-R28*N28*(1+0.8*R28*N28)),4) -> 0.9584
A29: HFO SERV 1 | B29: VLSFO | C29: GAUGE | D29: 94 | E29: 24 | F29: Nil | G29: 0 | H29: =IF(E29="","",E29-G29) -> 24 | I29: =IF(E29="","",S29) -> 0.9451 | J29: 0.9862 | K29: =IF(E29="","",H29*I29) -> 22.6824 | L29: =IF(A29="","",ROUND(SUM(K29*J29),3)) -> 22.369 | M29: =(J29-0.0011)*K29 -> 22.344432 | N29: =D29-15 -> 79 | O29: =J29*1000 -> 986.2 | P29: =IF(J29>0.8385,186.9696,IF(J29>0.7875,594.5418,IF(J29>0.77,2680.3206,346.4228))) -> 186.9696 | Q29: =IF(J29>0.8385,0.4862,IF(J29>0.7875,0,IF(J29>0.77,-0.00336312,0.4388))) -> 0.4862 | R29: =IF(OR(J29>0.7876,J29=0.7876),(P29/O29^2)+(Q29/O29),IF(OR(J29>0.7701,J29=0.7701),(P29/O29^2)+Q29,(P29/O29^2)+(Q29/O29))) -> 0.00068524223 | S29: =ROUND(EXP(-R29*N29*(1+0.8*R29*N29)),4) -> 0.9451
A30: HFO SETT 1 | B30: VLSFO | C30: GAUGE | D30: 32 | E30: 0.1 | F30: Nil | G30: 0 | H30: =IF(E30="","",E30-G30) -> 0.1 | I30: =IF(E30="","",S30) -> 0.9883 | J30: 0.9862 | K30: =IF(E30="","",H30*I30) -> 0.09883 | L30: =IF(A30="","",ROUND(SUM(K30*J30),3)) -> 0.097 | M30: =(J30-0.0011)*K30 -> 0.097357433 | N30: =D30-15 -> 17 | O30: =J30*1000 -> 986.2 | P30: =IF(J30>0.8385,186.9696,IF(J30>0.7875,594.5418,IF(J30>0.77,2680.3206,346.4228))) -> 186.9696 | Q30: =IF(J30>0.8385,0.4862,IF(J30>0.7875,0,IF(J30>0.77,-0.00336312,0.4388))) -> 0.4862 | R30: =IF(OR(J30>0.7876,J30=0.7876),(P30/O30^2)+(Q30/O30),IF(OR(J30>0.7701,J30=0.7701),(P30/O30^2)+Q30,(P30/O30^2)+(Q30/O30))) -> 0.00068524223 | S30: =ROUND(EXP(-R30*N30*(1+0.8*R30*N30)),4) -> 0.9883
A31: OVERFLOW | B31: VLSFO | C31: GAUGE | D31: 0 | E31: 0 | F31: Nil | G31: 0 | H31: =IF(E31="","",E31-G31) -> 0 | I31: =IF(E31="","",S31) -> 1.0102 | J31: 0.9908 | K31: =IF(E31="","",H31*I31) -> 0 | L31: =IF(A31="","",ROUND(SUM(K31*J31),3)) -> 0 | M31: =(J31-0.0011)*K31 -> 0 | N31: =D31-15 -> -15 | O31: =J31*1000 -> 990.8 | P31: =IF(J31>0.8385,186.9696,IF(J31>0.7875,594.5418,IF(J31>0.77,2680.3206,346.4228))) -> 186.9696 | Q31: =IF(J31>0.8385,0.4862,IF(J31>0.7875,0,IF(J31>0.77,-0.00336312,0.4388))) -> 0.4862 | R31: =IF(OR(J31>0.7876,J31=0.7876),(P31/O31^2)+(Q31/O31),IF(OR(J31>0.7701,J31=0.7701),(P31/O31^2)+Q31,(P31/O31^2)+(Q31/O31))) -> 0.00068117248 | S31: =ROUND(EXP(-R31*N31*(1+0.8*R31*N31)),4) -> 1.0102
A32: XXXXX | B32: VLSFO | C32: 0 | D32: 0 | E32: 0 | F32: Nil | G32: 0 | H32: =IF(E32="","",E32-G32) -> 0 | I32: =IF(E32="","",S32) -> 1.0102 | J32: 0.9908 | K32: =IF(E32="","",H32*I32) -> 0 | L32: =IF(A32="","",ROUND(SUM(K32*J32),3)) -> 0 | M32: =(J32-0.0011)*K32 -> 0 | N32: =D32-15 -> -15 | O32: =J32*1000 -> 990.8 | P32: =IF(J32>0.8385,186.9696,IF(J32>0.7875,594.5418,IF(J32>0.77,2680.3206,346.4228))) -> 186.9696 | Q32: =IF(J32>0.8385,0.4862,IF(J32>0.7875,0,IF(J32>0.77,-0.00336312,0.4388))) -> 0.4862 | R32: =IF(OR(J32>0.7876,J32=0.7876),(P32/O32^2)+(Q32/O32),IF(OR(J32>0.7701,J32=0.7701),(P32/O32^2)+Q32,(P32/O32^2)+(Q32/O32))) -> 0.00068117248 | S32: =ROUND(EXP(-R32*N32*(1+0.8*R32*N32)),4) -> 1.0102
G33: =D39 -> 0 | H33: =IF(E33="","",E33-G33) | I33: =IF(E33="","",S33) | K33: =IF(E33="","",H33*I33) | L33: =IF(A33="","",ROUND(SUM(K33*J33),3)) | M33: =(J33-0.0011)*K33 -> #VALUE! | N33: =IF(D33="",0,D33-15) -> 0 | O33: =IF(J33="",0,J33*1000) -> 0 | P33: =IF(J33="",0,IF(J33>0.8385,186.9696,IF(J33>0.7875,594.5418,IF(J33>0.77,2680.3206,346.4228)))) -> 0 | Q33: =IF(J33="",0,IF(J33>0.8385,0.4862,IF(J33>0.7875,0,IF(J33>0.77,-0.00336312,0.4388)))) -> 0 | R33: =IF(OR(J33="",J33=0),0,IF(OR(J33>0.7876,J33=0.7876),(P33/O33^2)+(Q33/O33),IF(OR(J33>0.7701,J33=0.7701),(P33/O33^2)+Q33,(P33/O33^2)+(Q33/O33)))) -> 0 | S33: =IF(OR(J33="",J33=0),0,ROUND(EXP(-R33*N33*(1+0.8*R33*N33)),4)) -> 0
G34: 0 | H34: =IF(E34="","",E34-G34) | I34: =IF(E34="","",S34) | K34: =IF(E34="","",H34*I34) | L34: =IF(A34="","",ROUND(SUM(K34*J34),3)) | M34: =(J34-0.0011)*K34 -> #VALUE! | N34: =IF(D34="",0,D34-15) -> 0 | O34: =IF(J34="",0,J34*1000) -> 0 | P34: =IF(J34="",0,IF(J34>0.8385,186.9696,IF(J34>0.7875,594.5418,IF(J34>0.77,2680.3206,346.4228)))) -> 0 | Q34: =IF(J34="",0,IF(J34>0.8385,0.4862,IF(J34>0.7875,0,IF(J34>0.77,-0.00336312,0.4388)))) -> 0 | R34: =IF(OR(J34="",J34=0),0,IF(OR(J34>0.7876,J34=0.7876),(P34/O34^2)+(Q34/O34),IF(OR(J34>0.7701,J34=0.7701),(P34/O34^2)+Q34,(P34/O34^2)+(Q34/O34)))) -> 0 | S34: =IF(OR(J34="",J34=0),0,ROUND(EXP(-R34*N34*(1+0.8*R34*N34)),4)) -> 0
G35: 0 | H35: =IF(E35="","",E35-G35) | I35: =IF(E35="","",S35) | K35: =IF(E35="","",H35*I35) | L35: =IF(A35="","",ROUND(SUM(K35*J35),3)) | M35: =(J35-0.0011)*K35 -> #VALUE! | N35: =IF(D35="",0,D35-15) -> 0 | O35: =IF(J35="",0,J35*1000) -> 0 | P35: =IF(J35="",0,IF(J35>0.8385,186.9696,IF(J35>0.7875,594.5418,IF(J35>0.77,2680.3206,346.4228)))) -> 0 | Q35: =IF(J35="",0,IF(J35>0.8385,0.4862,IF(J35>0.7875,0,IF(J35>0.77,-0.00336312,0.4388)))) -> 0 | R35: =IF(OR(J35="",J35=0),0,IF(OR(J35>0.7876,J35=0.7876),(P35/O35^2)+(Q35/O35),IF(OR(J35>0.7701,J35=0.7701),(P35/O35^2)+Q35,(P35/O35^2)+(Q35/O35)))) -> 0 | S35: =IF(OR(J35="",J35=0),0,ROUND(EXP(-R35*N35*(1+0.8*R35*N35)),4)) -> 0
G36: 0 | H36: =IF(E36="","",E36-G36) | I36: =IF(E36="","",S36) | K36: =IF(E36="","",H36*I36) | L36: =IF(A36="","",ROUND(SUM(K36*J36),3)) | M36: =(J36-0.0011)*K36 -> #VALUE! | N36: =IF(D36="",0,D36-15) -> 0 | O36: =IF(J36="",0,J36*1000) -> 0 | P36: =IF(J36="",0,IF(J36>0.8385,186.9696,IF(J36>0.7875,594.5418,IF(J36>0.77,2680.3206,346.4228)))) -> 0 | Q36: =IF(J36="",0,IF(J36>0.8385,0.4862,IF(J36>0.7875,0,IF(J36>0.77,-0.00336312,0.4388)))) -> 0 | R36: =IF(OR(J36="",J36=0),0,IF(OR(J36>0.7876,J36=0.7876),(P36/O36^2)+(Q36/O36),IF(OR(J36>0.7701,J36=0.7701),(P36/O36^2)+Q36,(P36/O36^2)+(Q36/O36)))) -> 0 | S36: =IF(OR(J36="",J36=0),0,ROUND(EXP(-R36*N36*(1+0.8*R36*N36)),4)) -> 0
G37: 0 | H37: =IF(E37="","",E37-G37) | I37: =IF(E37="","",S37) | K37: =IF(E37="","",H37*I37) | L37: =IF(A37="","",ROUND(SUM(K37*J37),3)) | M37: =(J37-0.0011)*K37 -> #VALUE! | N37: =SUM(N21:N36) -> 240
G38: 0 | H38: =IF(E38="","",E38-G38) | I38: =IF(E38="","",S38) | K38: =IF(E38="","",H38*I38) | L38: =IF(A38="","",ROUND(SUM(K38*J38),3)) | M38: =(J38-0.0011)*K38 -> #VALUE!
G39: 0 | H39: =IF(E39="","",E39-G39) | I39: =IF(E39="","",S39) | K39: =IF(E39="","",H39*I39) | L39: =IF(A39="","",ROUND(SUM(K39*J39),3)) | M39: =(J39-0.0011)*K39 -> #VALUE!
G40: 0 | H40: =IF(E40="","",E40-G40) | I40: =IF(E40="","",S40) | K40: =IF(E40="","",H40*I40) | L40: =IF(A40="","",ROUND(SUM(K40*J40),3)) | M40: =(J40-0.0011)*K40 -> #VALUE!
G41: 0 | H41: =IF(E41="","",E41-G41) | I41: =IF(E41="","",S41) | K41: =IF(E41="","",H41*I41) | L41: =IF(A41="","",ROUND(SUM(K41*J41),3)) | M41: =(J41-0.0011)*K41 -> #VALUE!
A42: TOTAL | H42: =SUM(H21:H36) -> 687.61 | K42: =SUM(K21:K36) -> 680.37207 | L42: =SUM(L21:L36) -> 670.982 | M42: =SUM(M21:M36) -> #VALUE!
J44: LOG BOOK | K44: 661.9 | L44: Dif | M44: =M42-K44 -> #VALUE!
N45: =D50-15 -> 9 | O45: =J50*1000 -> 986.2 | P45: =IF(J50>0.8385,186.9696,IF(J50>0.7875,594.5418,IF(J50>0.77,2680.3206,346.4228))) -> 186.9696 | Q45: =IF(J50>0.8385,0.4862,IF(J50>0.7875,0,IF(J50>0.77,-0.00336312,0.4388))) -> 0.4862 | R45: =IF(OR(J50>0.7876,J50=0.7876),(P45/O45^2)+(Q45/O45),IF(OR(J50>0.7701,J50=0.7701),(P45/O45^2)+Q45,(P45/O45^2)+(Q45/O45))) -> 0.00068524223 | S45: =ROUND(EXP(-R45*N45*(1+0.8*R45*N45)),4) -> 0.9938
A46: AFTER BUNKERING | N46: =D51-15 -> 9 | O46: =J51*1000 -> 986.2 | P46: =IF(J51>0.8385,186.9696,IF(J51>0.7875,594.5418,IF(J51>0.77,2680.3206,346.4228))) -> 186.9696 | Q46: =IF(J51>0.8385,0.4862,IF(J51>0.7875,0,IF(J51>0.77,-0.00336312,0.4388))) -> 0.4862 | R46: =IF(OR(J51>0.7876,J51=0.7876),(P46/O46^2)+(Q46/O46),IF(OR(J51>0.7701,J51=0.7701),(P46/O46^2)+Q46,(P46/O46^2)+(Q46/O46))) -> 0.00068524223 | S46: =ROUND(EXP(-R46*N46*(1+0.8*R46*N46)),4) -> 0.9938
A47: Draft Fore: | B47: 0 | C47: m | D47: Draft Aft: | E47: 0 | F47: m | G47: List: | H47: 0 | I47: Trim Correction Applied: | K47: Yes | L47: METRIC TONS | N47: =D52-15 -> 27 | O47: =J52*1000 -> 989.6 | P47: =IF(J52>0.8385,186.9696,IF(J52>0.7875,594.5418,IF(J52>0.77,2680.3206,346.4228))) -> 186.9696 | Q47: =IF(J52>0.8385,0.4862,IF(J52>0.7875,0,IF(J52>0.77,-0.00336312,0.4388))) -> 0.4862 | R47: =IF(OR(J52>0.7876,J52=0.7876),(P47/O47^2)+(Q47/O47),IF(OR(J52>0.7701,J52=0.7701),(P47/O47^2)+Q47,(P47/O47^2)+(Q47/O47))) -> 0.00068222971 | S47: =ROUND(EXP(-R47*N47*(1+0.8*R47*N47)),4) -> 0.9815
A48: Tank nº | B48: Grade | C48: Sounding/ Ullage (m) | D48: Deg C | E48: Total Vol Observed (m3) | F48: Free Water | H48: Gross Obs Vol (m3) | I48: 9 | J48: Density (S.G.) at 15° C | K48: Gross Std Vol @15° C | L48: IN VAC | M48: IN AIR | N48: =D53-15 -> 27 | O48: =J53*1000 -> 989.6 | P48: =IF(J53>0.8385,186.9696,IF(J53>0.7875,594.5418,IF(J53>0.77,2680.3206,346.4228))) -> 186.9696 | Q48: =IF(J53>0.8385,0.4862,IF(J53>0.7875,0,IF(J53>0.77,-0.00336312,0.4388))) -> 0.4862 | R48: =IF(OR(J53>0.7876,J53=0.7876),(P48/O48^2)+(Q48/O48),IF(OR(J53>0.7701,J53=0.7701),(P48/O48^2)+Q48,(P48/O48^2)+(Q48/O48))) -> 0.00068222971 | S48: =ROUND(EXP(-R48*N48*(1+0.8*R48*N48)),4) -> 0.9815
F49: Dip | G49: Vol | N49: =D54-15 -> 9 | O49: =J54*1000 -> 986.2 | P49: =IF(J54>0.8385,186.9696,IF(J54>0.7875,594.5418,IF(J54>0.77,2680.3206,346.4228))) -> 186.9696 | Q49: =IF(J54>0.8385,0.4862,IF(J54>0.7875,0,IF(J54>0.77,-0.00336312,0.4388))) -> 0.4862 | R49: =IF(OR(J54>0.7876,J54=0.7876),(P49/O49^2)+(Q49/O49),IF(OR(J54>0.7701,J54=0.7701),(P49/O49^2)+Q49,(P49/O49^2)+(Q49/O49))) -> 0.00068524223 | S49: =ROUND(EXP(-R49*N49*(1+0.8*R49*N49)),4) -> 0.9938
...

Sheet Sounding Barge
H2: MARINE SURVEYORS & CONSULTANTS
I3: Av. Almirante Cochrane, 203 sl 81 - Santos /BR
H4: surveyors@naabsa.com | Naabsa.com | TEL: 55 13 3394-0655
B7: BARGE´S SOUNDING/ULLAGE REPORT
B9: Name of Vessel: | D9: ='Vessel Ullage'!C8 -> Densa Pelican | H9: Grade of Fuel Ordered: | J9: ='Vessel Ullage'!I8 -> VLSFO
H10: Location of Survey: | J10: ='Vessel Ullage'!I9 -> Santos Port - LOCAL
B11: Name of Barges : | D11: ='Vessel Ullage'!C10 -> XXXXXXXXXXXX | H11: Date of Survey: | J11: ='Vessel Ullage'!I10 -> January 00th, 2023
H12: Time: | J12: ='Vessel Ullage'!I11 -> 00:00 x 00:00 h/LT
B16: BEFORE TRANSFER | J16: FLOWMETER | K16: 5008777.6 | N16: m3
B17: Draft Fore: | C17: 4.1 | D17: m | E17: Draft Aft: | F17: 4.55 | G17: m | H17: List: | I17: 0.45 | J17: Trim Correction Applied: | L17: YES | M17: METRIC TONS
B18: Tank nº | C18: Grade | D18: Sounding / Ullage (m) | E18: Deg C | F18: Total Vol Observed (m3) | G18: Free Water | I18: Gross Obs Vol (m3) | J18: VCF TAB 54B | K18: Density (S.G.) at 15° C | L18: Gross Std Vol @15° C | M18: IN VAC | N18: IN AIR
G19: Dip | H19: Vol
B20: 1 BB | C20: VLSFO | D20: 0.993 | E20: 40.5 | F20: 448.674 | G20: Nil | H20: 0 | I20: =IF(F20="","",F20-H20) -> 448.674 | J20: =IF(F20="","",T20) -> 0.9815 | K20: =B63 -> 0.9475 | L20: =IF(F20="","",I20*J20) -> 440.37353 | M20: =IF(B20="","",ROUND(SUM(L20*K20),3)) -> 417.254 | N20: =(K20-0.0011)*L20 -> 416.76951 | O20: =IF(E20="","",E20-15) -> 25.5 | P20: =K20*1000 -> 947.5 | Q20: =IF(K20>0.8385,186.9696,IF(K20>0.7875,594.5418,IF(K20>0.77,2680.3206,346.4228))) -> 186.9696 | R20: =IF(K20>0.8385,0.4862,IF(K20>0.7875,0,IF(K20>0.77,-0.00336312,0.4388))) -> 0.4862 | S20: =IF(OR(K20>0.7876,K20=0.7876),(Q20/P20^2)+(R20/P20),IF(OR(K20>0.7701,K20=0.7701),(Q20/P20^2)+R20,(Q20/P20^2)+(R20/P20))) -> 0.00072140305 | T20: =ROUND(EXP(-S20*O20*(1+0.8*S20*O20)),4) -> 0.9815
B21: 1 BE | C21: VLSFO | D21: 1.022 | E21: 40.5 | F21: 446.125 | G21: Nil | H21: 0 | I21: =IF(F21="","",F21-H21) -> 446.125 | J21: =IF(F21="","",T21) -> 0.9815 | K21: =B63 -> 0.9475 | L21: =IF(F21="","",I21*J21) -> 437.87169 | M21: =IF(B21="","",ROUND(SUM(L21*K21),3)) -> 414.883 | N21: =(K21-0.0011)*L21 -> 414.40177 | O21: =E21-15 -> 25.5 | P21: =K21*1000 -> 947.5 | Q21: =IF(K21>0.8385,186.9696,IF(K21>0.7875,594.5418,IF(K21>0.77,2680.3206,346.4228))) -> 186.9696 | R21: =IF(K21>0.8385,0.4862,IF(K21>0.7875,0,IF(K21>0.77,-0.00336312,0.4388))) -> 0.4862 | S21: =IF(OR(K21>0.7876,K21=0.7876),(Q21/P21^2)+(R21/P21),IF(OR(K21>0.7701,K21=0.7701),(Q21/P21^2)+R21,(Q21/P21^2)+(R21/P21))) -> 0.00072140305 | T21: =ROUND(EXP(-S21*O21*(1+0.8*S21*O21)),4) -> 0.9815
B22: 2 BB | C22: VLSFO | D22: 0.946 | E22: 44.5 | F22: 472.481 | H22: 0 | I22: =IF(F22="","",F22-H22) -> 472.481 | J22: =IF(F22="","",T22) -> 0.9786 | K22: =B63 -> 0.9475 | L22: =IF(F22="","",I22*J22) -> 462.36991 | M22: =IF(B22="","",ROUND(SUM(L22*K22),3)) -> 438.095 | N22: =(K22-0.0011)*L22 -> 437.58688 | O22: =E22-15 -> 29.5 | P22: =K22*1000 -> 947.5 | Q22: =IF(K22>0.8385,186.9696,IF(K22>0.7875,594.5418,IF(K22>0.77,2680.3206,346.4228))) -> 186.9696 | R22: =IF(K22>0.8385,0.4862,IF(K22>0.7875,0,IF(K22>0.77,-0.00336312,0.4388))) -> 0.4862 | S22: =IF(OR(K22>0.7876,K22=0.7876),(Q22/P22^2)+(R22/P22),IF(OR(K22>0.7701,K22=0.7701),(Q22/P22^2)+R22,(Q22/P22^2)+(R22/P22))) -> 0.00072140305 | T22: =ROUND(EXP(-S22*O22*(1+0.8*S22*O22)),4) -> 0.9786
B23: 2 BE | C23: VLSFO | D23: 1.026 | E23: 44.5 | F23: 465.274 | G23: Nil | H23: 0 | I23: =IF(F23="","",F23-H23) -> 465.274 | J23: =IF(F23="","",T23) -> 0.9786 | K23: =B63 -> 0.9475 | L23: =IF(F23="","",I23*J23) -> 455.31714 | M23: =IF(B23="","",ROUND(SUM(L23*K23),3)) -> 431.413 | N23: =(K23-0.0011)*L23 -> 430.91214 | O23: =E23-15 -> 29.5 | P23: =K23*1000 -> 947.5 | Q23: =IF(K23>0.8385,186.9696,IF(K23>0.7875,594.5418,IF(K23>0.77,2680.3206,346.4228))) -> 186.9696 | R23: =IF(K23>0.8385,0.4862,IF(K23>0.7875,0,IF(K23>0.77,-0.00336312,0.4388))) -> 0.4862 | S23: =IF(OR(K23>0.7876,K23=0.7876),(Q23/P23^2)+(R23/P23),IF(OR(K23>0.7701,K23=0.7701),(Q23/P23^2)+R23,(Q23/P23^2)+(R23/P23))) -> 0.00072140305 | T23: =ROUND(EXP(-S23*O23*(1+0.8*S23*O23)),4) -> 0.9786
B24: 3 BB | C24: VLSFO | D24: 10 | E24: 43 | F24: 438.905 | G24: Nil | H24: 0 | I24: =IF(F24="","",F24-H24) -> 438.905 | J24: =IF(F24="","",T24) -> 0.9797 | K24: =B63 -> 0.9475 | L24: =IF(F24="","",I24*J24) -> 429.99523 | M24: =IF(B24="","",ROUND(SUM(L24*K24),3)) -> 407.42 | N24: =(K24-0.0011)*L24 -> 406.94748 | O24: =E24-15 -> 28 | P24: =K24*1000 -> 947.5 | Q24: =IF(K24>0.8385,186.9696,IF(K24>0.7875,594.5418,IF(K24>0.77,2680.3206,346.4228))) -> 186.9696 | R24: =IF(K24>0.8385,0.4862,IF(K24>0.7875,0,IF(K24>0.77,-0.00336312,0.4388))) -> 0.4862 | S24: =IF(OR(K24>0.7876,K24=0.7876),(Q24/P24^2)+(R24/P24),IF(OR(K24>0.7701,K24=0.7701),(Q24/P24^2)+R24,(Q24/P24^2)+(R24/P24))) -> 0.00072140305 | T24: =ROUND(EXP(-S24*O24*(1+0.8*S24*O24)),4) -> 0.9797
B25: 3 BE | C25: VLSFO | D25: 10 | E25: 43 | F25: 434.058 | G25: Nil | H25: 0 | I25: =IF(F25="","",F25-H25) -> 434.058 | J25: =IF(F25="","",T25) -> 0.9797 | K25: =B63 -> 0.9475 | L25: =IF(F25="","",I25*J25) -> 425.24662 | M25: =IF(B25="","",ROUND(SUM(L25*K25),3)) -> 402.921 | N25: =(K25-0.0011)*L25 -> 402.4534 | O25: =E25-15 -> 28 | P25: =K25*1000 -> 947.5 | Q25: =IF(K25>0.8385,186.9696,IF(K25>0.7875,594.5418,IF(K25>0.77,2680.3206,346.4228))) -> 186.9696 | R25: =IF(K25>0.8385,0.4862,IF(K25>0.7875,0,IF(K25>0.77,-0.00336312,0.4388))) -> 0.4862 | S25: =IF(OR(K25>0.7876,K25=0.7876),(Q25/P25^2)+(R25/P25),IF(OR(K25>0.7701,K25=0.7701),(Q25/P25^2)+R25,(Q25/P25^2)+(R25/P25))) -> 0.00072140305 | T25: =ROUND(EXP(-S25*O25*(1+0.8*S25*O25)),4) -> 0.9797
B26: 4 BB | C26: VLSFO | D26: 0.975 | E26: 0 | F26: 0 | G26: Nil | H26: 0 | I26: =IF(F26="","",F26-H26) -> 0 | J26: =IF(F26="","",T26) -> 1.0108 | K26: =B63 -> 0.9475 | L26: =IF(F26="","",I26*J26) -> 0 | M26: =IF(B26="","",ROUND(SUM(L26*K26),3)) -> 0 | N26: =(K26-0.0011)*L26 -> 0 | O26: =E26-15 -> -15 | P26: =K26*1000 -> 947.5 | Q26: =IF(K26>0.8385,186.9696,IF(K26>0.7875,594.5418,IF(K26>0.77,2680.3206,346.4228))) -> 186.9696 | R26: =IF(K26>0.8385,0.4862,IF(K26>0.7875,0,IF(K26>0.77,-0.00336312,0.4388))) -> 0.4862 | S26: =IF(OR(K26>0.7876,K26=0.7876),(Q26/P26^2)+(R26/P26),IF(OR(K26>0.7701,K26=0.7701),(Q26/P26^2)+R26,(Q26/P26^2)+(R26/P26))) -> 0.00072140305 | T26: =ROUND(EXP(-S26*O26*(1+0.8*S26*O26)),4) -> 1.0108
B27: 4 BE | C27: VLSFO | D27: 1.043 | E27: 0 | F27: 0 | G27: Nil | H27: 0 | I27: =IF(F27="","",F27-H27) -> 0 | J27: =IF(F27="","",T27) -> 1.0108 | K27: =B63 -> 0.9475 | L27: =IF(F27="","",I27*J27) -> 0 | M27: =IF(B27="","",ROUND(SUM(L27*K27),3)) -> 0 | N27: =(K27-0.0011)*L27 -> 0 | O27: =E27-15 -> -15 | P27: =K27*1000 -> 947.5 | Q27: =IF(K27>0.8385,186.9696,IF(K27>0.7875,594.5418,IF(K27>0.77,2680.3206,346.4228))) -> 186.9696 | R27: =IF(K27>0.8385,0.4862,IF(K27>0.7875,0,IF(K27>0.77,-0.00336312,0.4388))) -> 0.4862 | S27: =IF(OR(K27>0.7876,K27=0.7876),(Q27/P27^2)+(R27/P27),IF(OR(K27>0.7701,K27=0.7701),(Q27/P27^2)+R27,(Q27/P27^2)+(R27/P27))) -> 0.00072140305 | T27: =ROUND(EXP(-S27*O27*(1+0.8*S27*O27)),4) -> 1.0108
B28: 5BE | C28: VLSFO | I28: =IF(F28="","",F28-G29) | J28: =IF(F28="","",T28) | K28: =B63 -> 0.9475 | L28: =IF(F28="","",I28*J28) | M28: =IF(B28="","",ROUND(SUM(L28*K28),3)) -> #VALUE! | N28: =IF(F28="",0,(K28-0.0011)*L28) -> 0 | O28: =IF(E28="",0,E28-15) -> 0 | P28: =IF(K28="",0,K28*1000) -> 947.5 | Q28: =IF(K28="",0,IF(K28>0.8385,186.9696,IF(K28>0.7875,594.5418,IF(K28>0.77,2680.3206,346.4228)))) -> 186.9696 | R28: =IF(K28="",0,IF(K28>0.8385,0.4862,IF(K28>0.7875,0,IF(K28>0.77,-0.00336312,0.4388)))) -> 0.4862 | S28: =IF(OR(K28="",K28=0),0,IF(OR(K28>0.7876,K28=0.7876),(Q28/P28^2)+(R28/P28),IF(OR(K28>0.7701,K28=0.7701),(Q28/P28^2)+R28,(Q28/P28^2)+(R28/P28)))) -> 0.00072140305 | T28: =IF(OR(K28="",K28=0),0,ROUND(EXP(-S28*O28*(1+0.8*S28*O28)),4)) -> 1
I29: =IF(F29="","",F29-H29) | J29: =IF(F29="","",T29) | K29: =B63 -> 0.9475 | L29: =IF(F29="","",I29*J29) | M29: =IF(B29="","",ROUND(SUM(L29*K29),3)) | N29: =IF(F29="",0,(K29-0.0011)*L29) -> 0 | O29: =IF(E29="",0,E29-15) -> 0 | P29: =IF(K29="",0,K29*1000) -> 947.5 | Q29: =IF(K29="",0,IF(K29>0.8385,186.9696,IF(K29>0.7875,594.5418,IF(K29>0.77,2680.3206,346.4228)))) -> 186.9696 | R29: =IF(K29="",0,IF(K29>0.8385,0.4862,IF(K29>0.7875,0,IF(K29>0.77,-0.00336312,0.4388)))) -> 0.4862 | S29: =IF(OR(K29="",K29=0),0,IF(OR(K29>0.7876,K29=0.7876),(Q29/P29^2)+(R29/P29),IF(OR(K29>0.7701,K29=0.7701),(Q29/P29^2)+R29,(Q29/P29^2)+(R29/P29)))) -> 0.00072140305 | T29: =IF(OR(K29="",K29=0),0,ROUND(EXP(-S29*O29*(1+0.8*S29*O29)),4)) -> 1
I30: =IF(F30="","",F30-H30) | J30: =IF(F30="","",T30) | K30: =B63 -> 0.9475 | L30: =IF(F30="","",I30*J30) | M30: =IF(B30="","",ROUND(SUM(L30*K30),3))
I31: =IF(F31="","",F31-H31) | J31: =IF(F31="","",T31) | K31: =B63 -> 0.9475 | L31: =IF(F31="","",I31*J31) | M31: =IF(B31="","",ROUND(SUM(L31*K31),3))
I32: =IF(F32="","",F32-H32) | J32: =IF(F32="","",T32) | K32: =B63 -> 0.9475 | L32: =IF(F32="","",I32*J32) | M32: =IF(B32="","",ROUND(SUM(L32*K32),3))
I33: =IF(F33="","",F33-H33) | J33: =IF(F33="","",T33) | K33: =B63 -> 0.9475 | L33: =IF(F33="","",I33*J33) | M33: =IF(B33="","",ROUND(SUM(L33*K33),3))
I34: =IF(F34="","",F34-H34) | J34: =IF(F34="","",T34) | K34: =B63 -> 0.9475 | L34: =IF(F34="","",I34*J34) | M34: =IF(B34="","",ROUND(SUM(L34*K34),3))
B35: Total | I35: =SUM(I20:I29) -> 2705.517 | J35: =MEDIAN(J20:J29) -> 0.9806 | K35: =MEDIAN(K20:K29) -> 0.9475 | L35: =SUM(L20:L29) -> 2651.1741 | M35: =ROUND(SUM(M20:M29),3) -> #VALUE! | N35: =SUM(N20:N29) -> 2509.0712
X36: =SUM(L20:L27) -> 2651.1741
O37: =IF(E44="","",E44-15) -> 25.5 | P37: =K44*1000 -> 947.5 | Q37: =IF(K44>0.8385,186.9696,IF(K44>0.7875,594.5418,IF(K44>0.77,2680.3206,346.4228))) -> 186.9696 | R37: =IF(K44>0.8385,0.4862,IF(K44>0.7875,0,IF(K44>0.77,-0.00336312,0.4388))) -> 0.4862 | S37: =IF(OR(K44>0.7876,K44=0.7876),(Q37/P37^2)+(R37/P37),IF(OR(K44>0.7701,K44=0.7701),(Q37/P37^2)+R37,(Q37/P37^2)+(R37/P37))) -> 0.00072140305 | T37: =ROUND(EXP(-S37*O37*(1+0.8*S37*O37)),4) -> 0.9815 | W37: =I35-I59 -> 624.677 | X37: =SUM(L44:L51) -> 2038.9835 | Y37: =624.8*0.9799 -> 612.24152
O38: =E45-15 -> 25.5 | P38: =K45*1000 -> 947.5 | Q38: =IF(K45>0.8385,186.9696,IF(K45>0.7875,594.5418,IF(K45>0.77,2680.3206,346.4228))) -> 186.9696 | R38: =IF(K45>0.8385,0.4862,IF(K45>0.7875,0,IF(K45>0.77,-0.00336312,0.4388))) -> 0.4862 | S38: =IF(OR(K45>0.7876,K45=0.7876),(Q38/P38^2)+(R38/P38),IF(OR(K45>0.7701,K45=0.7701),(Q38/P38^2)+R38,(Q38/P38^2)+(R38/P38))) -> 0.00072140305 | T38: =ROUND(EXP(-S38*O38*(1+0.8*S38*O38)),4) -> 0.9815 | W38: =W37*0.9799 -> 612.12099 | X38: =X36-X37 -> 612.19063 | Y38: =Y37*0.9475 -> 580.09884
O39: =E46-15 -> 29.5 | P39: =K46*1000 -> 947.5 | Q39: =IF(K46>0.8385,186.9696,IF(K46>0.7875,594.5418,IF(K46>0.77,2680.3206,346.4228))) -> 186.9696 | R39: =IF(K46>0.8385,0.4862,IF(K46>0.7875,0,IF(K46>0.77,-0.00336312,0.4388))) -> 0.4862 | S39: =IF(OR(K46>0.7876,K46=0.7876),(Q39/P39^2)+(R39/P39),IF(OR(K46>0.7701,K46=0.7701),(Q39/P39^2)+R39,(Q39/P39^2)+(R39/P39))) -> 0.00072140305 | T39: =ROUND(EXP(-S39*O39*(1+0.8*S39*O39)),4) -> 0.9786 | W39: =W38*0.9475 -> 579.98464
B40: AFTER RECEIVING | J40: FLOWMETER | K40: 5009402.4 | N40: m3 | O40: =E47-15 -> 29.5 | P40: =K47*1000 -> 947.5 | Q40: =IF(K47>0.8385,186.9696,IF(K47>0.7875,594.5418,IF(K47>0.77,2680.3206,346.4228))) -> 186.9696 | R40: =IF(K47>0.8385,0.4862,IF(K47>0.7875,0,IF(K47>0.77,-0.00336312,0.4388))) -> 0.4862 | S40: =IF(OR(K47>0.7876,K47=0.7876),(Q40/P40^2)+(R40/P40),IF(OR(K47>0.7701,K47=0.7701),(Q40/P40^2)+R40,(Q40/P40^2)+(R40/P40))) -> 0.00072140305 | T40: =ROUND(EXP(-S40*O40*(1+0.8*S40*O40)),4) -> 0.9786
B41: Draft Fore: | C41: 3.05 | D41: m | E41: Draft Aft: | F41: 4.15 | G41: m | H41: List: | I41: 1.1 | J41: Trim Correction Applied: | L41: YES | M41: METRIC TONS | O41: =E48-15 -> 28 | P41: =K48*1000 -> 947.5 | Q41: =IF(K48>0.8385,186.9696,IF(K48>0.7875,594.5418,IF(K48>0.77,2680.3206,346.4228))) -> 186.9696 | R41: =IF(K48>0.8385,0.4862,IF(K48>0.7875,0,IF(K48>0.77,-0.00336312,0.4388))) -> 0.4862 | S41: =IF(OR(K48>0.7876,K48=0.7876),(Q41/P41^2)+(R41/P41),IF(OR(K48>0.7701,K48=0.7701),(Q41/P41^2)+R41,(Q41/P41^2)+(R41/P41))) -> 0.00072140305 | T41: =ROUND(EXP(-S41*O41*(1+0.8*S41*O41)),4) -> 0.9797
B42: Tank nº | C42: Grade | D42: Sounding / Ullage (m) | E42: Deg C | F42: Total Vol Observed (m3) | G42: Free Water | I42: Gross Obs Vol (m3) | J42: VCF TAB 54B | K42: Density (S.G.) at 15° C | L42: Gross Std Vol @15° C | M42: IN VAC | N42: IN AIR | O42: =E49-15 -> 28 | P42: =K49*1000 -> 947.5 | Q42: =IF(K49>0.8385,186.9696,IF(K49>0.7875,594.5418,IF(K49>0.77,2680.3206,346.4228))) -> 186.9696 | R42: =IF(K49>0.8385,0.4862,IF(K49>0.7875,0,IF(K49>0.77,-0.00336312,0.4388))) -> 0.4862 | S42: =IF(OR(K49>0.7876,K49=0.7876),(Q42/P42^2)+(R42/P42),IF(OR(K49>0.7701,K49=0.7701),(Q42/P42^2)+R42,(Q42/P42^2)+(R42/P42))) -> 0.00072140305 | T42: =ROUND(EXP(-S42*O42*(1+0.8*S42*O42)),4) -> 0.9797
G43: Dip | H43: Vol | O43: =E50-15 -> -15 | P43: =K50*1000 -> 947.5 | Q43: =IF(K50>0.8385,186.9696,IF(K50>0.7875,594.5418,IF(K50>0.77,2680.3206,346.4228))) -> 186.9696 | R43: =IF(K50>0.8385,0.4862,IF(K50>0.7875,0,IF(K50>0.77,-0.00336312,0.4388))) -> 0.4862 | S43: =IF(OR(K50>0.7876,K50=0.7876),(Q43/P43^2)+(R43/P43),IF(OR(K50>0.7701,K50=0.7701),(Q43/P43^2)+R43,(Q43/P43^2)+(R43/P43))) -> 0.00072140305 | T43: =ROUND(EXP(-S43*O43*(1+0.8*S43*O43)),4) -> 1.0108
B44: =B20 -> 1 BB | C44: =C20 -> VLSFO | D44: 2.27 | E44: 40.5 | F44: 323.826 | G44: Nil | H44: 0 | I44: =IF(F44="","",F44-H44) -> 323.826 | J44: =IF(F44="","",T37) -> 0.9815 | K44: =K20 -> 0.9475 | L44: =IF(F44="","",I44*J44) -> 317.83522 | M44: =IF(B44="","",ROUND(SUM(L44*K44),3)) -> 301.149 | N44: =(K44-0.0011)*L44 -> 300.79925 | O44: =E51-15 -> -15 | P44: =K51*1000 -> 947.5 | Q44: =IF(K51>0.8385,186.9696,IF(K51>0.7875,594.5418,IF(K51>0.77,2680.3206,346.4228))) -> 186.9696 | R44: =IF(K51>0.8385,0.4862,IF(K51>0.7875,0,IF(K51>0.77,-0.00336312,0.4388))) -> 0.4862 | S44: =IF(OR(K51>0.7876,K51=0.7876),(Q44/P44^2)+(R44/P44),IF(OR(K51>0.7701,K51=0.7701),(Q44/P44^2)+R44,(Q44/P44^2)+(R44/P44))) -> 0.00072140305 | T44: =ROUND(EXP(-S44*O44*(1+0.8*S44*O44)),4) -> 1.0108
B45: =B21 -> 1 BE | C45: =C21 -> VLSFO | D45: 2.23 | E45: 40.5 | F45: 327.706 | G45: Nil | H45: 0 | I45: =IF(F45="","",F45-H45) -> 327.706 | J45: =IF(F45="","",T38) -> 0.9815 | K45: =K21 -> 0.9475 | L45: =IF(F45="","",I45*J45) -> 321.64344 | M45: =IF(B45="","",ROUND(SUM(L45*K45),3)) -> 304.757 | N45: =(K45-0.0011)*L45 -> 304.40335 | O45: =IF(E52="",0,E52-15) -> -15 | P45: =IF(K52="",0,K52*1000) -> 947.5 | Q45: =IF(K52="",0,IF(K52>0.8385,186.9696,IF(K52>0.7875,594.5418,IF(K52>0.77,2680.3206,346.4228)))) -> 186.9696 | R45: =IF(K52="",0,IF(K52>0.8385,0.4862,IF(K52>0.7875,0,IF(K52>0.77,-0.00336312,0.4388)))) -> 0.4862 | S45: =IF(OR(K52="",K52=0),0,IF(OR(K52>0.7876,K52=0.7876),(Q45/P45^2)+(R45/P45),IF(OR(K52>0.7701,K52=0.7701),(Q45/P45^2)+R45,(Q45/P45^2)+(R45/P45)))) -> 0.00072140305 | T45: =IF(OR(K52="",K52=0),0,ROUND(EXP(-S45*O45*(1+0.8*S45*O45)),4)) -> 1.0108
B46: =B22 -> 2 BB | C46: =C22 -> VLSFO | D46: 2.02 | E46: 44.5 | F46: 361.259 | G46: Nil | H46: 0 | I46: =IF(F46="","",F46-H46) -> 361.259 | J46: =IF(F46="","",T39) -> 0.9786 | K46: =K22 -> 0.9475 | L46: =IF(F46="","",I46*J46) -> 353.52806 | M46: =IF(B46="","",ROUND(SUM(L46*K46),3)) -> 334.968 | N46: =(K46-0.0011)*L46 -> 334.57895 | O46: =IF(E53="",0,E53-15) -> 0 | P46: =IF(K53="",0,K53*1000) -> 947.5 | Q46: =IF(K53="",0,IF(K53>0.8385,186.9696,IF(K53>0.7875,594.5418,IF(K53>0.77,2680.3206,346.4228)))) -> 186.9696 | R46: =IF(K53="",0,IF(K53>0.8385,0.4862,IF(K53>0.7875,0,IF(K53>0.77,-0.00336312,0.4388)))) -> 0.4862 | S46: =IF(OR(K53="",K53=0),0,IF(OR(K53>0.7876,K53=0.7876),(Q46/P46^2)+(R46/P46),IF(OR(K53>0.7701,K53=0.7701),(Q46/P46^2)+R46,(Q46/P46^2)+(R46/P46)))) -> 0.00072140305 | T46: =IF(OR(K53="",K53=0),0,ROUND(EXP(-S46*O46*(1+0.8*S46*O46)),4)) -> 1
B47: =B23 -> 2 BE | C47: =C23 -> VLSFO | D47: 2.085 | E47: 44.5 | F47: 355.31 | G47: Nil | H47: 0 | I47: =IF(F47="","",F47-H47) -> 355.31 | J47: =IF(F47="","",T40) -> 0.9786 | K47: =K23 -> 0.9475 | L47: =IF(F47="","",I47*J47) -> 347.70637 | M47: =IF(B47="","",ROUND(SUM(L47*K47),3)) -> 329.452 | N47: =(K47-0.0011)*L47 -> 329.0693
...

Sheet Time Log
F2: MARINE SURVEYORS & CONSULTANTS
G3: Av. Almirante Cochrane, 203 sl 81 - Santos /BR
F4: surveyors@naabsa.com | Naabsa.com | TEL: 55 13 3394-0655
A7: TIME LOG
A9: Name of Vessel: | C9: ='Vessel Ullage'!C8 -> Densa Pelican | E9: Grade of Fuel Ordered: | G9: ='Vessel Ullage'!I8 -> VLSFO
E10: Location of Survey: | G10: ='Vessel Ullage'!I9 -> Santos Port - LOCAL
A11: Name of Barges : | C11: ='Vessel Ullage'!C10 -> XXXXXXXXXXXX | E11: Date of Survey: | G11: ='Vessel Ullage'!I10 -> January 00th, 2023
E12: Time: | G12: ='Vessel Ullage'!I11 -> 00:00 x 00:00 h/LT
A15: Operation | D15: Date | E15: Times
A16: POB for berthing | D16: 43612 | E16: 0.36666667
A17: Gangway down | D17: 43612 | E17: 0.45138889 | Y17: 21418555
A18: Awaiting barge | D18: 43612 | E18: 0.45833333 | F18: 0.48611111
A19: Bunker Barge arrived | D19: 43737 | E19: 0.48611111
A20: Surveyor onboard | D20: 43737 | E20: 0.47569444
A21: Meeting between C/E and surveyor | D21: 43737 | E21: 0.48958333 | F21: 0.5
A22: Initial Soundings/Ullage - Vessel | D22: 43737 | E22: 0.5 | F22: 0.52083333
A23: All fast / Barge ready | D23: 43737 | E23: 0.49652778
A24: Initial Soundings/Ullage - Barge | D24: 43737 | E24: 0.51041667 | F24: 0.53125
A25: Hose Connected | D25: 43737 | E25: 0.52430556
A26: Bunkering operation | D26: 43737 | E26: 0.52777778 | F26: 0.64236111
A27: Final Soundings/Ullage - Barge | D27: 43737 | E27: 0.64583333 | F27: 0.66666667
A28: Final Soundings/Ullage - Vessel | D28: 43737 | E28: 0.66666667 | F28: 0.6875
A29: Calculation | D29: 43737 | E29: 0.6875 | F29: 0.70833333
A30: Documents signed | D30: 43737 | E30: 0.70833333 | F30: 0.72916667
A31: Hose disconnected | D31: 43737 | E31: 0.66666667 | F31: 0.6875
A32: Surveyor off board | D32: 43737 | E32: 0.72916667
A35: Stoppages/Delays
A36: NO DELAYS
A45: Remark:
A56: CHIEF ENGINEER: | C56: ='Vessel Ullage'!D96 -> Enjaynes, Leo Mark Abellare | G56: SURVEYOR: | I56: ='Vessel Ullage'!K96 -> Abreu, Wagner de

Sheet Sample Report
G2: MARINE SURVEYORS & CONSULTANTS
G3: Av. Almirante Cochrane, 203 sl 81 - Santos /BR
F4: surveyors@naabsa.com | Naabsa.com | TEL: 55 13 3394-0655
A9: SAMPLE REPORT
A11: Name of Vessel: | C11: ='Vessel Ullage'!C8 -> Densa Pelican | E11: Grade of Fuel Ordered: | G11: ='Vessel Ullage'!I8 -> VLSFO
E12: Location of Survey: | G12: ='Vessel Ullage'!I9 -> Santos Port - LOCAL
A13: Name of Barges : | C13: ='Vessel Ullage'!C10 -> XXXXXXXXXXXX | E13: Date of Survey: | G13: ='Vessel Ullage'!I10 -> January 00th, 2023
E14: Time: | G14: ='Vessel Ullage'!I11 -> 00:00 x 00:00 h/LT
A17: SAMPLES WERE TAKEN DURING BUNKERING
A19: Name of barge | D19: ='Vessel Ullage'!C10 -> XXXXXXXXXXXX
A20: Grade | D20: ='Vessel Ullage'!I8 -> VLSFO
A21: Tank number | D21: 1BB, 1BE, 2BB, 2BE, 4BB and 4BE
A22: Sampling Method | D22: DRIPPING
A23: Sampling Point | D23: SHIP MANIFOLD | F23: BARGE MANIFOLD
A24: Quantity of Sample | D24: 6 x 0,5 L | F24: 4 x 0,5 L
A25: SAMPLES | D25: VESSEL | F25: BARGE
A26: Retained by Chife Engineer | D26: 2279520 | F26: 0007216
A27: Retained by Supplier`s Representative | D27: 2279521 | F27: 0007217
A28: Laboratory | D28: 2279519 | F28: 2708875
A29: Marpol Sample | D29: 2279522 | F29: 0007218
A30: Surveyor Samples | D30: 2279524 | F30: NA
A33: Remarks(IF ANY)
A38: CHIEF ENGINEER: | C38: ='Vessel Ullage'!D96 -> Enjaynes, Leo Mark Abellare | G38: SURVEYOR: | I38: ='Vessel Ullage'!K96 -> Abreu, Wagner de

Sheet Letter of Protest
G2: MARINE SURVEYORS & CONSULTANTS
H3: Av. Almirante Cochrane, 203 sl 81 - Santos /BR
G4: surveyors@naabsa.com | Naabsa.com | TEL: 55 13 3394-0655
A8: Name of Vessel: | C8: ='Vessel Ullage'!C8 -> Densa Pelican | F8: Grade of Fuel Ordered: | H8: ='Sounding Barge'!J9 -> VLSFO
F9: Location of Survey: | H9: ='Vessel Ullage'!I9 -> Santos Port - LOCAL
A10: Name of Barges : | C10: ='Vessel Ullage'!C10 -> XXXXXXXXXXXX | F10: Date of Survey: | H10: ='Vessel Ullage'!I10 -> January 00th, 2023
F11: Time: | H11: ='Vessel Ullage'!I11 -> 00:00 x 00:00 h/LT
A13: To: Supplier or representative
A15: C/c: CHIEF ENGINEER
F18: LETTER OF PROTEST
A23: Vessel : | B23: ='Vessel Ullage'!C8 -> Densa Pelican | F23: Date : | G23: ='Vessel Ullage'!I10 -> January 00th, 2023
A25: Location : | B25: ='Vessel Ullage'!I9 -> Santos Port - LOCAL | F25: Product : | G25: ='Vessel Ullage'!I8 -> VLSFO
A28: We have been appointed as Marine Surveyors to act on behalf of our Principals and the following | L28: ||||||||||||||||||||||||||||||\\\\\\\\\\\\\\\\\\\\\\\\\\\\\\\\\\\\\\\\\\\\\\\\\\\\\\\\\\\\\\\\\\\\\\\\\\\\\\\\\\\\\\\|\\\\\\ZZZZZZZZZZZZZZZZZZZZZZZZZZZZZZZZZZZZZZZZZZZZZZZZZZZZZZZZZZZZZZZZZZZZZZZZZZZZ666666
A29: figures is brought to your attention to the differences bellow:
F32: difference
D33: BDN | E33: NAABSA | F33: MT | G33: %
D34: ='Vessel Ullage'!L80 -> 580 | E34: ='Vessel Ullage'!L81 -> #VALUE! | F34: ='Vessel Ullage'!L82 -> #VALUE! | G34: ='Vessel Ullage'!L83 -> #VALUE!
A36: We hereby reserve the right of our Principals to make reference to the above at a later date.
A43: Signed for receipt:
A45: VESSEL/BARGE REPRESENTATIVE : | G45: SURVEYOR: | I45: ='Vessel Ullage'!K96 -> Abreu, Wagner de
A46: STAMPED AND SIGNED

Sheet VacuoAr
A1: Density at 15C | B1: FCW Vacuo-Ar
A2: 0.5 | B2: 0.99775
A3: 0.5191 | B3: 0.99775
A4: 0.5192 | B4: 0.99785
A5: 0.5421 | B5: 0.99785
A6: 0.5422 | B6: 0.99795
A7: 0.5673 | B7: 0.99795
A8: 0.5674 | B8: 0.99805
A9: 0.595 | B9: 0.99805
A10: 0.5951 | B10: 0.99815
A11: 0.6255 | B11: 0.99815
A12: 0.6256 | B12: 0.99825
A13: 0.6593 | B13: 0.99825
... A29: 1.1 | B29: 0.99905
