Workbook

Sheet Vessel Ullage
H2: MARINE SURVEYORS & CONSULTANTS
H3: Av. Ana Costa, 433 sl 184 - Santos /BR
H4: surveyors@naabsa.com | Naabsa.com | TEL: 55 13 3394-0655
B6: VESSEL´S SOUNDING/ULLAGE REPORT
B8: Name of Vessel: | D8: CAPE KENNEDY | H8: Grade of Fuel Ordered: | J8: VLSFO 0.5% S
H9: Location of Survey: | J9: Paranagua Port - Shed 212
B10: Name of Barges : | D10: OMS V | H10: Date of Survey: | J10: April 14th, 2026
H11: Time: | J11: 16:50 x 22:00 h/LT
B17: BEFORE BUNKERING
B18: Draft Fore: | C18: 4.4 | D18: m | E18: Draft Aft: | F18: 7.6 | G18: m | H18: List: | I18: 0 | J18: Trim Correction Applied: | L18: Yes | M18: METRIC TONS
B19: Tank nº | C19: Grade | D19: Sounding/ Ullage (m) | E19: Deg °C | F19: Total Vol Observed (m3) | G19: Free Water | I19: Gross Obs Vol (m3) | J19: VCF TAB 54B | K19: Density (S.G.) at 15° C | L19: Gross Std Vol @15° C | M19: IN VAC | N19: IN AIR
G20: Dip | H20: Vol
B21: HFO 1P | C21: VLSFO | D21: 4,96 U | E21: 32 | F21: 2.96 | G21: Nil | H21: 0 | I21: =IF(F21="","",F21-H21) -> 2.96 | J21: =IF(F21="","",T21) -> 0.988 | K21: 0.9643 | L21: =IF(F21="","",I21*J21) -> 2.92448 | M21: =IF(B21="","",ROUND(SUM(L21*K21),3)) -> 2.82 | N21: =(K21-0.0011)*L21 -> 2.8168591 | O21: =E21-15 -> 17 | P21: =K21*1000 -> 964.3 | Q21: =IF(K21>0.8385,186.9696,IF(K21>0.7875,594.5418,IF(K21>0.77,2680.3206,346.4228))) -> 186.9696 | R21: =IF(K21>0.8385,0.4862,IF(K21>0.7875,0,IF(K21>0.77,-0.00336312,0.4388))) -> 0.4862 | S21: =IF(OR(K21>0.7876,K21=0.7876),(Q21/P21^2)+(R21/P21),IF(OR(K21>0.7701,K21=0.7701),(Q21/P21^2)+R21,(Q21/P21^2)+(R21/P21))) -> 0.00070526965 | T21: =ROUND(EXP(-S21*O21*(1+0.8*S21*O21)),4) -> 0.988
B22: HFO 1S | C22: VLSFO | D22: 3,41 U | E22: 32 | F22: 71.88 | G22: Nil | H22: 0 | I22: =IF(F22="","",F22-H22) -> 71.88 | J22: =IF(F22="","",T22) -> 0.988 | K22: 0.9643 | L22: =IF(F22="","",I22*J22) -> 71.01744 | M22: =IF(B22="","",ROUND(SUM(L22*K22),3)) -> 68.482 | N22: =(K22-0.0011)*L22 -> 68.403998 | O22: =E22-15 -> 17 | P22: =K22*1000 -> 964.3 | Q22: =IF(K22>0.8385,186.9696,IF(K22>0.7875,594.5418,IF(K22>0.77,2680.3206,346.4228))) -> 186.9696 | R22: =IF(K22>0.8385,0.4862,IF(K22>0.7875,0,IF(K22>0.77,-0.00336312,0.4388))) -> 0.4862 | S22: =IF(OR(K22>0.7876,K22=0.7876),(Q22/P22^2)+(R22/P22),IF(OR(K22>0.7701,K22=0.7701),(Q22/P22^2)+R22,(Q22/P22^2)+(R22/P22))) -> 0.00070526965 | T22: =ROUND(EXP(-S22*O22*(1+0.8*S22*O22)),4) -> 0.988
B23: HFO 2P | C23: VLSFO | D23: 1,03 U | E23: 30 | F23: 385.02 | G23: Nil | H23: 0 | I23: =IF(F23="","",F23-H23) -> 385.02 | J23: =IF(F23="","",T23) -> 0.9894 | K23: 0.9643 | L23: =IF(F23="","",I23*J23) -> 380.93879 | M23: =IF(B23="","",ROUND(SUM(L23*K23),3)) -> 367.339 | N23: =(K23-0.0011)*L23 -> 366.92024 | O23: =E23-15 -> 15 | P23: =K23*1000 -> 964.3 | Q23: =IF(K23>0.8385,186.9696,IF(K23>0.7875,594.5418,IF(K23>0.77,2680.3206,346.4228))) -> 186.9696 | R23: =IF(K23>0.8385,0.4862,IF(K23>0.7875,0,IF(K23>0.77,-0.00336312,0.4388))) -> 0.4862 | S23: =IF(OR(K23>0.7876,K23=0.7876),(Q23/P23^2)+(R23/P23),IF(OR(K23>0.7701,K23=0.7701),(Q23/P23^2)+R23,(Q23/P23^2)+(R23/P23))) -> 0.00070526965 | T23: =ROUND(EXP(-S23*O23*(1+0.8*S23*O23)),4) -> 0.9894
B24: HFO 2S | C24: VLSFO | D24: 1,21 U | E24: 29 | F24: 357.74 | G24: Nil | H24: 0 | I24: =IF(F24="","",F24-H24) -> 357.74 | J24: =IF(F24="","",T24) -> 0.9901 | K24: 0.9643 | L24: =IF(F24="","",I24*J24) -> 354.19837 | M24: =IF(B24="","",ROUND(SUM(L24*K24),3)) -> 341.553 | N24: =(K24-0.0011)*L24 -> 341.16387 | O24: =E24-15 -> 14 | P24: =K24*1000 -> 964.3 | Q24: =IF(K24>0.8385,186.9696,IF(K24>0.7875,594.5418,IF(K24>0.77,2680.3206,346.4228))) -> 186.9696 | R24: =IF(K24>0.8385,0.4862,IF(K24>0.7875,0,IF(K24>0.77,-0.00336312,0.4388))) -> 0.4862 | S24: =IF(OR(K24>0.7876,K24=0.7876),(Q24/P24^2)+(R24/P24),IF(OR(K24>0.7701,K24=0.7701),(Q24/P24^2)+R24,(Q24/P24^2)+(R24/P24))) -> 0.00070526965 | T24: =ROUND(EXP(-S24*O24*(1+0.8*S24*O24)),4) -> 0.9901
B25: LSHFO P | C25: VLSFO | D25: 0.08 | E25: 48 | F25: 2.3 | G25: Nil | H25: 0 | I25: =IF(F25="","",F25-H25) -> 2.3 | J25: =IF(F25="","",T25) -> 0.9766 | K25: 0.9643 | L25: =IF(F25="","",I25*J25) -> 2.24618 | M25: =IF(B25="","",ROUND(SUM(L25*K25),3)) -> 2.166 | N25: =(K25-0.0011)*L25 -> 2.1635206 | O25: =E25-15 -> 33 | P25: =K25*1000 -> 964.3 | Q25: =IF(K25>0.8385,186.9696,IF(K25>0.7875,594.5418,IF(K25>0.77,2680.3206,346.4228))) -> 186.9696 | R25: =IF(K25>0.8385,0.4862,IF(K25>0.7875,0,IF(K25>0.77,-0.00336312,0.4388))) -> 0.4862 | S25: =IF(OR(K25>0.7876,K25=0.7876),(Q25/P25^2)+(R25/P25),IF(OR(K25>0.7701,K25=0.7701),(Q25/P25^2)+R25,(Q25/P25^2)+(R25/P25))) -> 0.00070526965 | T25: =ROUND(EXP(-S25*O25*(1+0.8*S25*O25)),4) -> 0.9766
B26: LSHFO S | C26: VLSFO | D26: 3,08 U | E26: 32 | F26: 100 | G26: Nil | H26: 0 | I26: =IF(F26="","",F26-H26) -> 100 | J26: =IF(F26="","",T26) -> 0.988 | K26: 0.9643 | L26: =IF(F26="","",I26*J26) -> 98.8 | M26: =IF(B26="","",ROUND(SUM(L26*K26),3)) -> 95.273 | N26: =(K26-0.0011)*L26 -> 95.16416 | O26: =E26-15 -> 17 | P26: =K26*1000 -> 964.3 | Q26: =IF(K26>0.8385,186.9696,IF(K26>0.7875,594.5418,IF(K26>0.77,2680.3206,346.4228))) -> 186.9696 | R26: =IF(K26>0.8385,0.4862,IF(K26>0.7875,0,IF(K26>0.77,-0.00336312,0.4388))) -> 0.4862 | S26: =IF(OR(K26>0.7876,K26=0.7876),(Q26/P26^2)+(R26/P26),IF(OR(K26>0.7701,K26=0.7701),(Q26/P26^2)+R26,(Q26/P26^2)+(R26/P26))) -> 0.00070526965 | T26: =ROUND(EXP(-S26*O26*(1+0.8*S26*O26)),4) -> 0.988
B27: HFO SETT | C27: VLSFO | D27: 5,03 U | E27: 90 | F27: 38.8 | G27: Nil | H27: 0 | I27: =IF(F27="","",F27-H27) -> 38.8 | J27: =IF(F27="","",T27) -> 0.9442 | K27: 0.9353 | L27: =IF(F27="","",I27*J27) -> 36.63496 | M27: =IF(B27="","",ROUND(SUM(L27*K27),3)) -> 34.265 | N27: =(K27-0.0011)*L27 -> 34.22438 | O27: =E27-15 -> 75 | P27: =K27*1000 -> 935.3 | Q27: =IF(K27>0.8385,186.9696,IF(K27>0.7875,594.5418,IF(K27>0.77,2680.3206,346.4228))) -> 186.9696 | R27: =IF(K27>0.8385,0.4862,IF(K27>0.7875,0,IF(K27>0.77,-0.00336312,0.4388))) -> 0.4862 | S27: =IF(OR(K27>0.7876,K27=0.7876),(Q27/P27^2)+(R27/P27),IF(OR(K27>0.7701,K27=0.7701),(Q27/P27^2)+R27,(Q27/P27^2)+(R27/P27))) -> 0.000733565 | T27: =ROUND(EXP(-S27*O27*(1+0.8*S27*O27)),4) -> 0.9442
B28: HFO SERV | C28: VLSFO | D28: 3,03 U | E28: 89 | F28: 58.2 | G28: Nil | H28: 0 | I28: =IF(F28="","",F28-H28) -> 58.2 | J28: =IF(F28="","",T28) -> 0.9449 | K28: 0.9353 | L28: =IF(F28="","",I28*J28) -> 54.99318 | M28: =IF(B28="","",ROUND(SUM(L28*K28),3)) -> 51.435 | N28: =(K28-0.0011)*L28 -> 51.374629 | O28: =E28-15 -> 74 | P28: =K28*1000 -> 935.3 | Q28: =IF(K28>0.8385,186.9696,IF(K28>0.7875,594.5418,IF(K28>0.77,2680.3206,346.4228))) -> 186.9696 | R28: =IF(K28>0.8385,0.4862,IF(K28>0.7875,0,IF(K28>0.77,-0.00336312,0.4388))) -> 0.4862 | S28: =IF(OR(K28>0.7876,K28=0.7876),(Q28/P28^2)+(R28/P28),IF(OR(K28>0.7701,K28=0.7701),(Q28/P28^2)+R28,(Q28/P28^2)+(R28/P28))) -> 0.000733565 | T28: =ROUND(EXP(-S28*O28*(1+0.8*S28*O28)),4) -> 0.9449
B29: LSFO SETT | C29: VLSFO | D29: 6,28 U | E29: 48 | F29: 18.3 | G29: Nil | H29: 0 | I29: =IF(F29="","",F29-H29) -> 18.3 | J29: =IF(F29="","",T29) -> 0.9758 | K29: 0.9419 | L29: =IF(F29="","",I29*J29) -> 17.85714 | M29: =IF(B29="","",ROUND(SUM(L29*K29),3)) -> 16.82 | N29: =(K29-0.0011)*L29 -> 16.799997 | O29: =E29-15 -> 33 | P29: =K29*1000 -> 941.9 | Q29: =IF(K29>0.8385,186.9696,IF(K29>0.7875,594.5418,IF(K29>0.77,2680.3206,346.4228))) -> 186.9696 | R29: =IF(K29>0.8385,0.4862,IF(K29>0.7875,0,IF(K29>0.77,-0.00336312,0.4388))) -> 0.4862 | S29: =IF(OR(K29>0.7876,K29=0.7876),(Q29/P29^2)+(R29/P29),IF(OR(K29>0.7701,K29=0.7701),(Q29/P29^2)+R29,(Q29/P29^2)+(R29/P29))) -> 0.00072693768 | T29: =ROUND(EXP(-S29*O29*(1+0.8*S29*O29)),4) -> 0.9758
B30: LSFO SERV | C30: VLSFO | D30: 0 | E30: 62 | F30: 0.3 | G30: Nil | H30: 0 | I30: =IF(F30="","",F30-H30) -> 0.3 | J30: =IF(F30="","",T30) -> 0.9655 | K30: 0.9419 | L30: =IF(F30="","",I30*J30) -> 0.28965 | M30: =IF(B30="","",ROUND(SUM(L30*K30),3)) -> 0.273 | N30: =(K30-0.0011)*L30 -> 0.27250272 | O30: =E30-15 -> 47 | P30: =K30*1000 -> 941.9 | Q30: =IF(K30>0.8385,186.9696,IF(K30>0.7875,594.5418,IF(K30>0.77,2680.3206,346.4228))) -> 186.9696 | R30: =IF(K30>0.8385,0.4862,IF(K30>0.7875,0,IF(K30>0.77,-0.00336312,0.4388))) -> 0.4862 | S30: =IF(OR(K30>0.7876,K30=0.7876),(Q30/P30^2)+(R30/P30),IF(OR(K30>0.7701,K30=0.7701),(Q30/P30^2)+R30,(Q30/P30^2)+(R30/P30))) -> 0.00072693768 | T30: =ROUND(EXP(-S30*O30*(1+0.8*S30*O30)),4) -> 0.9655
B31: OVERFLOW | C31: VLSFO | D31: 0.36 | E31: 30 | F31: 2.4 | G31: Nil | H31: 0 | I31: =IF(F31="","",F31-H31) -> 2.4 | J31: =IF(F31="","",T31) -> 0.989 | K31: 0.9353 | L31: =IF(F31="","",I31*J31) -> 2.3736 | M31: =IF(B31="","",ROUND(SUM(L31*K31),3)) -> 2.22 | N31: =(K31-0.0011)*L31 -> 2.2174171 | O31: =E31-15 -> 15 | P31: =K31*1000 -> 935.3 | Q31: =IF(K31>0.8385,186.9696,IF(K31>0.7875,594.5418,IF(K31>0.77,2680.3206,346.4228))) -> 186.9696 | R31: =IF(K31>0.8385,0.4862,IF(K31>0.7875,0,IF(K31>0.77,-0.00336312,0.4388))) -> 0.4862 | S31: =IF(OR(K31>0.7876,K31=0.7876),(Q31/P31^2)+(R31/P31),IF(OR(K31>0.7701,K31=0.7701),(Q31/P31^2)+R31,(Q31/P31^2)+(R31/P31))) -> 0.000733565 | T31: =ROUND(EXP(-S31*O31*(1+0.8*S31*O31)),4) -> 0.989
B32: 4 | C32: VLSFO | D32: GAUGE | E32: 0 | F32: 0 | G32: Nil | H32: 0 | I32: =IF(F32="","",F32-H32) -> 0 | J32: =IF(F32="","",T32) -> 1.0115 | K32: 0.9 | L32: =IF(F32="","",I32*J32) -> 0 | M32: =IF(B32="","",ROUND(SUM(L32*K32),3)) -> 0 | N32: =(K32-0.0011)*L32 -> 0 | O32: =E32-15 -> -15 | P32: =K32*1000 -> 900 | Q32: =IF(K32>0.8385,186.9696,IF(K32>0.7875,594.5418,IF(K32>0.77,2680.3206,346.4228))) -> 186.9696 | R32: =IF(K32>0.8385,0.4862,IF(K32>0.7875,0,IF(K32>0.77,-0.00336312,0.4388))) -> 0.4862 | S32: =IF(OR(K32>0.7876,K32=0.7876),(Q32/P32^2)+(R32/P32),IF(OR(K32>0.7701,K32=0.7701),(Q32/P32^2)+R32,(Q32/P32^2)+(R32/P32))) -> 0.00077104889 | T32: =ROUND(EXP(-S32*O32*(1+0.8*S32*O32)),4) -> 1.0115
B33: TOTAL | I33: =SUM(I21:I32) -> 1037.9 | L33: =SUM(L21:L32) -> 1022.2738 | M33: =SUM(M21:M32) -> 982.646 | N33: =SUM(N21:N31) -> 981.52158 | O33: =SUM(O21:O32) -> 342
K35: LOG BOOK | L35: 981.5 | M35: Dif | N35: =N33-L35 -> 0.021577898
B37: AFTER BUNKERING
B38: Draft Fore: | C38: 4.8 | D38: m | E38: Draft Aft: | F38: 7.45 | G38: m | H38: List: | I38: 0 | J38: Trim Correction Applied: | L38: Yes | M38: METRIC TONS
B39: Tank nº | C39: Grade | D39: Sounding/ Ullage (m) | E39: Deg C | F39: Total Vol Observed (m3) | G39: Free Water | I39: Gross Obs Vol (m3) | J39: VCF TAB 54B | K39: Density (S.G.) at 15° C | L39: Gross Std Vol @15° C | M39: IN VAC | N39: IN AIR
G40: Dip | H40: Vol
B41: =B21 -> HFO 1P | C41: VLSFO | D41: 2.98 | E41: 42.6 | F41: 112.64 | G41: Nil | H41: 0 | I41: =IF(F41="","",F41-H41) -> 112.64 | J41: =IF(F41="","",T41) -> 0.9796 | K41: 0.935 | L41: =IF(F41="","",I41*J41) -> 110.34214 | M41: =IF(B41="","",ROUND(SUM(L41*K41),3)) -> 103.17 | N41: =(K41-0.0011)*L41 -> 103.04853 | O41: =E41-15 -> 27.6 | P41: =K41*1000 -> 935 | Q41: =IF(K41>0.8385,186.9696,IF(K41>0.7875,594.5418,IF(K41>0.77,2680.3206,346.4228))) -> 186.9696 | R41: =IF(K41>0.8385,0.4862,IF(K41>0.7875,0,IF(K41>0.77,-0.00336312,0.4388))) -> 0.4862 | S41: =IF(OR(K41>0.7876,K41=0.7876),(Q41/P41^2)+(R41/P41),IF(OR(K41>0.7701,K41=0.7701),(Q41/P41^2)+R41,(Q41/P41^2)+(R41/P41))) -> 0.00073386897 | T41: =ROUND(EXP(-S41*O41*(1+0.8*S41*O41)),4) -> 0.9796
B42: =B22 -> HFO 1S | C42: VLSFO | D42: =D22 -> 3,41 U | E42: =E22 -> 32 | F42: =F22 -> 71.88 | G42: Nil | H42: 0 | I42: =IF(F42="","",F42-H42) -> 71.88 | J42: =IF(F42="","",T42) -> 0.988 | K42: =K22 -> 0.9643 | L42: =IF(F42="","",I42*J42) -> 71.01744 | M42: =IF(B42="","",ROUND(SUM(L42*K42),3)) -> 68.482 | N42: =(K42-0.0011)*L42 -> 68.403998 | O42: =E42-15 -> 17 | P42: =K42*1000 -> 964.3 | Q42: =IF(K42>0.8385,186.9696,IF(K42>0.7875,594.5418,IF(K42>0.77,2680.3206,346.4228))) -> 186.9696 | R42: =IF(K42>0.8385,0.4862,IF(K42>0.7875,0,IF(K42>0.77,-0.00336312,0.4388))) -> 0.4862 | S42: =IF(OR(K42>0.7876,K42=0.7876),(Q42/P42^2)+(R42/P42),IF(OR(K42>0.7701,K42=0.7701),(Q42/P42^2)+R42,(Q42/P42^2)+(R42/P42))) -> 0.00070526965 | T42: =ROUND(EXP(-S42*O42*(1+0.8*S42*O42)),4) -> 0.988
B43: =B23 -> HFO 2P | C43: VLSFO | D43: =D23 -> 1,03 U | E43: =E23 -> 30 | F43: =F23 -> 385.02 | G43: Nil | H43: 0 | I43: =IF(F43="","",F43-H43) -> 385.02 | J43: =IF(F43="","",T43) -> 0.9894 | K43: =K23 -> 0.9643 | L43: =IF(F43="","",I43*J43) -> 380.93879 | M43: =IF(B43="","",ROUND(SUM(L43*K43),3)) -> 367.339 | N43: =(K43-0.0011)*L43 -> 366.92024 | O43: =E43-15 -> 15 | P43: =K43*1000 -> 964.3 | Q43: =IF(K43>0.8385,186.9696,IF(K43>0.7875,594.5418,IF(K43>0.77,2680.3206,346.4228))) -> 186.9696 | R43: =IF(K43>0.8385,0.4862,IF(K43>0.7875,0,IF(K43>0.77,-0.00336312,0.4388))) -> 0.4862 | S43: =IF(OR(K43>0.7876,K43=0.7876),(Q43/P43^2)+(R43/P43),IF(OR(K43>0.7701,K43=0.7701),(Q43/P43^2)+R43,(Q43/P43^2)+(R43/P43))) -> 0.00070526965 | T43: =ROUND(EXP(-S43*O43*(1+0.8*S43*O43)),4) -> 0.9894
B44: =B24 -> HFO 2S | C44: VLSFO | D44: =D24 -> 1,21 U | E44: =E24 -> 29 | F44: =F24 -> 357.74 | G44: Nil | H44: 0 | I44: =IF(F44="","",F44-H44) -> 357.74 | J44: =IF(F44="","",T44) -> 0.9901 | K44: =K24 -> 0.9643 | L44: =IF(F44="","",I44*J44) -> 354.19837 | M44: =IF(B44="","",ROUND(SUM(L44*K44),3)) -> 341.553 | N44: =(K44-0.0011)*L44 -> 341.16387 | O44: =E44-15 -> 14 | P44: =K44*1000 -> 964.3 | Q44: =IF(K44>0.8385,186.9696,IF(K44>0.7875,594.5418,IF(K44>0.77,2680.3206,346.4228))) -> 186.9696 | R44: =IF(K44>0.8385,0.4862,IF(K44>0.7875,0,IF(K44>0.77,-0.00336312,0.4388))) -> 0.4862 | S44: =IF(OR(K44>0.7876,K44=0.7876),(Q44/P44^2)+(R44/P44),IF(OR(K44>0.7701,K44=0.7701),(Q44/P44^2)+R44,(Q44/P44^2)+(R44/P44))) -> 0.00070526965 | T44: =ROUND(EXP(-S44*O44*(1+0.8*S44*O44)),4) -> 0.9901
B45: =B25 -> LSHFO P | C45: VLSFO | D45: =D25 -> 0.08 | E45: =E25 -> 48 | F45: =F25 -> 2.3 | G45: Nil | H45: 0 | I45: =IF(F45="","",F45-H45) -> 2.3 | J45: =IF(F45="","",T45) -> 0.9766 | K45: =K25 -> 0.9643 | L45: =IF(F45="","",I45*J45) -> 2.24618 | M45: =IF(B45="","",ROUND(SUM(L45*K45),3)) -> 2.166 | N45: =(K45-0.0011)*L45 -> 2.1635206 | O45: =E45-15 -> 33 | P45: =K45*1000 -> 964.3 | Q45: =IF(K45>0.8385,186.9696,IF(K45>0.7875,594.5418,IF(K45>0.77,2680.3206,346.4228))) -> 186.9696 | R45: =IF(K45>0.8385,0.4862,IF(K45>0.7875,0,IF(K45>0.77,-0.00336312,0.4388))) -> 0.4862 | S45: =IF(OR(K45>0.7876,K45=0.7876),(Q45/P45^2)+(R45/P45),IF(OR(K45>0.7701,K45=0.7701),(Q45/P45^2)+R45,(Q45/P45^2)+(R45/P45))) -> 0.00070526965 | T45: =ROUND(EXP(-S45*O45*(1+0.8*S45*O45)),4) -> 0.9766
B46: =B26 -> LSHFO S | C46: VLSFO | D46: =D26 -> 3,08 U | E46: =E26 -> 32 | F46: =F26 -> 100 | G46: Nil | H46: 0 | I46: =IF(F46="","",F46-H46) -> 100 | J46: =IF(F46="","",T46) -> 0.988 | K46: =K26 -> 0.9643 | L46: =IF(F46="","",I46*J46) -> 98.8 | M46: =IF(B46="","",ROUND(SUM(L46*K46),3)) -> 95.273 | N46: =(K46-0.0011)*L46 -> 95.16416 | O46: =E46-15 -> 17 | P46: =K46*1000 -> 964.3 | Q46: =IF(K46>0.8385,186.9696,IF(K46>0.7875,594.5418,IF(K46>0.77,2680.3206,346.4228))) -> 186.9696 | R46: =IF(K46>0.8385,0.4862,IF(K46>0.7875,0,IF(K46>0.77,-0.00336312,0.4388))) -> 0.4862 | S46: =IF(OR(K46>0.7876,K46=0.7876),(Q46/P46^2)+(R46/P46),IF(OR(K46>0.7701,K46=0.7701),(Q46/P46^2)+R46,(Q46/P46^2)+(R46/P46))) -> 0.00070526965 | T46: =ROUND(EXP(-S46*O46*(1+0.8*S46*O46)),4) -> 0.988
B47: =B27 -> HFO SETT | C47: VLSFO | D47: =D27 -> 5,03 U | E47: =E27 -> 90 | F47: =F27 -> 38.8 | G47: Nil | H47: 0 | I47: =IF(F47="","",F47-H47) -> 38.8 | J47: =IF(F47="","",T47) -> 0.9442 | K47: =K27 -> 0.9353 | L47: =IF(F47="","",I47*J47) -> 36.63496 | M47: =IF(B47="","",ROUND(SUM(L47*K47),3)) -> 34.265 | N47: =(K47-0.0011)*L47 -> 34.22438 | O47: =E47-15 -> 75 | P47: =K47*1000 -> 935.3 | Q47: =IF(K47>0.8385,186.9696,IF(K47>0.7875,594.5418,IF(K47>0.77,2680.3206,346.4228))) -> 186.9696 | R47: =IF(K47>0.8385,0.4862,IF(K47>0.7875,0,IF(K47>0.77,-0.00336312,0.4388))) -> 0.4862 | S47: =IF(OR(K47>0.7876,K47=0.7876),(Q47/P47^2)+(R47/P47),IF(OR(K47>0.7701,K47=0.7701),(Q47/P47^2)+R47,(Q47/P47^2)+(R47/P47))) -> 0.000733565 | T47: =ROUND(EXP(-S47*O47*(1+0.8*S47*O47)),4) -> 0.9442
B48: =B28 -> HFO SERV | C48: VLSFO | D48: =D28 -> 3,03 U | E48: =E28 -> 89 | F48: =F28 -> 58.2 | G48: Nil | H48: 0 | I48: =IF(F48="","",F48-H48) -> 58.2 | J48: =IF(F48="","",T48) -> 0.9449 | K48: =K28 -> 0.9353 | L48: =IF(F48="","",I48*J48) -> 54.99318 | M48: =IF(B48="","",ROUND(SUM(L48*K48),3)) -> 51.435 | N48: =(K48-0.0011)*L48 -> 51.374629 | O48: =E48-15 -> 74 | P48: =K48*1000 -> 935.3 | Q48: =IF(K48>0.8385,186.9696,IF(K48>0.7875,594.5418,IF(K48>0.77,2680.3206,346.4228))) -> 186.9696 | R48: =IF(K48>0.8385,0.4862,IF(K48>0.7875,0,IF(K48>0.77,-0.00336312,0.4388))) -> 0.4862 | S48: =IF(OR(K48>0.7876,K48=0.7876),(Q48/P48^2)+(R48/P48),IF(OR(K48>0.7701,K48=0.7701),(Q48/P48^2)+R48,(Q48/P48^2)+(R48/P48))) -> 0.000733565 | T48: =ROUND(EXP(-S48*O48*(1+0.8*S48*O48)),4) -> 0.9449
B49: =B29 -> LSFO SETT | C49: VLSFO | D49: =D29 -> 6,28 U | E49: =E29 -> 48 | F49: =F29 -> 18.3 | G49: Nil | H49: 0 | I49: =IF(F49="","",F49-H49) -> 18.3 | J49: =IF(F49="","",T49) -> 0.9758 | K49: =K29 -> 0.9419 | L49: =IF(F49="","",I49*J49) -> 17.85714 | M49: =IF(B49="","",ROUND(SUM(L49*K49),3)) -> 16.82 | N49: =(K49-0.0011)*L49 -> 16.799997 | O49: =E49-15 -> 33 | P49: =K49*1000 -> 941.9 | Q49: =IF(K49>0.8385,186.9696,IF(K49>0.7875,594.5418,IF(K49>0.77,2680.3206,346.4228))) -> 186.9696 | R49: =IF(K49>0.8385,0.4862,IF(K49>0.7875,0,IF(K49>0.77,-0.00336312,0.4388))) -> 0.4862 | S49: =IF(OR(K49>0.7876,K49=0.7876),(Q49/P49^2)+(R49/P49),IF(OR(K49>0.7701,K49=0.7701),(Q49/P49^2)+R49,(Q49/P49^2)+(R49/P49))) -> 0.00072693768 | T49: =ROUND(EXP(-S49*O49*(1+0.8*S49*O49)),4) -> 0.9758
B50: =B30 -> LSFO SERV | C50: VLSFO | D50: =D30 -> 0 | E50: =E30 -> 62 | F50: =F30 -> 0.3 | G50: Nil | H50: 0 | I50: =IF(F50="","",F50-H50) -> 0.3 | J50: =IF(F50="","",T50) -> 0.9655 | K50: =K30 -> 0.9419 | L50: =IF(F50="","",I50*J50) -> 0.28965 | M50: =IF(B50="","",ROUND(SUM(L50*K50),3)) -> 0.273 | N50: =(K50-0.0011)*L50 -> 0.27250272 | O50: =E50-15 -> 47 | P50: =K50*1000 -> 941.9 | Q50: =IF(K50>0.8385,186.9696,IF(K50>0.7875,594.5418,IF(K50>0.77,2680.3206,346.4228))) -> 186.9696 | R50: =IF(K50>0.8385,0.4862,IF(K50>0.7875,0,IF(K50>0.77,-0.00336312,0.4388))) -> 0.4862 | S50: =IF(OR(K50>0.7876,K50=0.7876),(Q50/P50^2)+(R50/P50),IF(OR(K50>0.7701,K50=0.7701),(Q50/P50^2)+R50,(Q50/P50^2)+(R50/P50))) -> 0.00072693768 | T50: =ROUND(EXP(-S50*O50*(1+0.8*S50*O50)),4) -> 0.9655
...

Sheet Sounding Barge
H2: MARINE SURVEYORS & CONSULTANTS
I3: Av. Ana Costa, 433 sl 184 - Santos /BR
H4: surveyors@naabsa.com | Naabsa.com | TEL: 55 13 3394-0655
B7: BARGE´S SOUNDING/ULLAGE REPORT
B9: Name of Vessel: | D9: ='Vessel Ullage'!D8 -> CAPE KENNEDY | H9: Grade of Fuel Ordered: | J9: ='Vessel Ullage'!J8 -> VLSFO 0.5% S
H10: Location of Survey: | J10: ='Vessel Ullage'!J9 -> Paranagua Port - Shed 212
B11: Name of Barges : | D11: ='Vessel Ullage'!D10 -> OMS V | H11: Date of Survey: | J11: ='Vessel Ullage'!J10 -> April 14th, 2026
H12: Time: | J12: ='Vessel Ullage'!J11 -> 16:50 x 22:00 h/LT
B16: BEFORE TRANSFER | J16: FLOWMETER | K16: N/A | N16: m3
B17: Draft Fore: | C17: 2.2 | D17: m | E17: Draft Aft: | F17: 2.3 | G17: m | H17: List: | I17: 0 | J17: Trim Correction Applied: | L17: YES | M17: METRIC TONS
B18: Tank nº | C18: Grade | D18: Sounding / Ullage (m) | E18: Deg C | F18: Total Vol Observed (m3) | G18: Free Water | I18: Gross Obs Vol (m3) | J18: VCF TAB 54B | K18: Density (S.G.) at 15° C | L18: Gross Std Vol @15° C | M18: IN VAC | N18: IN AIR
G19: Dip | H19: Vol
B20: 1BB | C20: VLSFO | D20: 2.946 | E20: 42 | F20: 205.085 | G20: Nil | H20: 0 | I20: =IF(F20="","",F20-H20) -> 205.085 | J20: =IF(F20="","",T20) -> 0.9801 | K20: =B47 -> 0.935 | L20: =IF(F20="","",I20*J20) -> 201.00381 | M20: =IF(B20="","",ROUND(SUM(L20*K20),3)) -> 187.939 | N20: =(K20-0.0011)*L20 -> 187.71746 | O20: =IF(E20="","",E20-15) -> 27 | P20: =K20*1000 -> 935 | Q20: =IF(K20>0.8385,186.9696,IF(K20>0.7875,594.5418,IF(K20>0.77,2680.3206,346.4228))) -> 186.9696 | R20: =IF(K20>0.8385,0.4862,IF(K20>0.7875,0,IF(K20>0.77,-0.00336312,0.4388))) -> 0.4862 | S20: =IF(OR(K20>0.7876,K20=0.7876),(Q20/P20^2)+(R20/P20),IF(OR(K20>0.7701,K20=0.7701),(Q20/P20^2)+R20,(Q20/P20^2)+(R20/P20))) -> 0.00073386897 | T20: =ROUND(EXP(-S20*O20*(1+0.8*S20*O20)),4) -> 0.9801
B21: 2BB | C21: VLSFO | D21: 4.39 | E21: 44 | F21: 97.191 | G21: Nil | H21: 0 | I21: =IF(F21="","",F21-H21) -> 97.191 | J21: =IF(F21="","",T21) -> 0.9786 | K21: =K20 -> 0.935 | L21: =IF(F21="","",I21*J21) -> 95.111113 | M21: =IF(B21="","",ROUND(SUM(L21*K21),3)) -> 88.929 | N21: =(K21-0.0011)*L21 -> 88.824268 | O21: =E21-15 -> 29 | P21: =K21*1000 -> 935 | Q21: =IF(K21>0.8385,186.9696,IF(K21>0.7875,594.5418,IF(K21>0.77,2680.3206,346.4228))) -> 186.9696 | R21: =IF(K21>0.8385,0.4862,IF(K21>0.7875,0,IF(K21>0.77,-0.00336312,0.4388))) -> 0.4862 | S21: =IF(OR(K21>0.7876,K21=0.7876),(Q21/P21^2)+(R21/P21),IF(OR(K21>0.7701,K21=0.7701),(Q21/P21^2)+R21,(Q21/P21^2)+(R21/P21))) -> 0.00073386897 | T21: =ROUND(EXP(-S21*O21*(1+0.8*S21*O21)),4) -> 0.9786
B22: 3BB | C22: VLSFO | D22: 4.343 | E22: 44 | F22: 50.152 | G22: Nil | H22: 0 | I22: =IF(F22="","",F22-H22) -> 50.152 | J22: =IF(F22="","",T22) -> 0.9786 | K22: =K21 -> 0.935 | L22: =IF(F22="","",I22*J22) -> 49.078747 | M22: =IF(B22="","",ROUND(SUM(L22*K22),3)) -> 45.889 | N22: =(K22-0.0011)*L22 -> 45.834642 | O22: =E22-15 -> 29 | P22: =K22*1000 -> 935 | Q22: =IF(K22>0.8385,186.9696,IF(K22>0.7875,594.5418,IF(K22>0.77,2680.3206,346.4228))) -> 186.9696 | R22: =IF(K22>0.8385,0.4862,IF(K22>0.7875,0,IF(K22>0.77,-0.00336312,0.4388))) -> 0.4862 | S22: =IF(OR(K22>0.7876,K22=0.7876),(Q22/P22^2)+(R22/P22),IF(OR(K22>0.7701,K22=0.7701),(Q22/P22^2)+R22,(Q22/P22^2)+(R22/P22))) -> 0.00073386897 | T22: =ROUND(EXP(-S22*O22*(1+0.8*S22*O22)),4) -> 0.9786
B23: 4BB | C23: VLSFO | D23: 2.931 | E23: 42 | F23: 210.425 | G23: Nil | H23: 0 | I23: =IF(F23="","",F23-H23) -> 210.425 | J23: =IF(F23="","",T23) -> 0.9801 | K23: =K22 -> 0.935 | L23: =IF(F23="","",I23*J23) -> 206.23754 | M23: =IF(B23="","",ROUND(SUM(L23*K23),3)) -> 192.832 | N23: =(K23-0.0011)*L23 -> 192.60524 | O23: =E23-15 -> 27 | P23: =K23*1000 -> 935 | Q23: =IF(K23>0.8385,186.9696,IF(K23>0.7875,594.5418,IF(K23>0.77,2680.3206,346.4228))) -> 186.9696 | R23: =IF(K23>0.8385,0.4862,IF(K23>0.7875,0,IF(K23>0.77,-0.00336312,0.4388))) -> 0.4862 | S23: =IF(OR(K23>0.7876,K23=0.7876),(Q23/P23^2)+(R23/P23),IF(OR(K23>0.7701,K23=0.7701),(Q23/P23^2)+R23,(Q23/P23^2)+(R23/P23))) -> 0.00073386897 | T23: =ROUND(EXP(-S23*O23*(1+0.8*S23*O23)),4) -> 0.9801
B24: 1BE | C24: VLSFO | D24: 2.905 | E24: 41.5 | F24: 208.71 | G24: Nil | H24: 0 | I24: =IF(F24="","",F24-H24) -> 208.71 | J24: =IF(F24="","",T24) -> 0.9804 | K24: =K23 -> 0.935 | L24: =IF(F24="","",I24*J24) -> 204.61928 | M24: =IF(B24="","",ROUND(SUM(L24*K24),3)) -> 191.319 | N24: =(K24-0.0011)*L24 -> 191.09395 | O24: =E24-15 -> 26.5 | P24: =K24*1000 -> 935 | Q24: =IF(K24>0.8385,186.9696,IF(K24>0.7875,594.5418,IF(K24>0.77,2680.3206,346.4228))) -> 186.9696 | R24: =IF(K24>0.8385,0.4862,IF(K24>0.7875,0,IF(K24>0.77,-0.00336312,0.4388))) -> 0.4862 | S24: =IF(OR(K24>0.7876,K24=0.7876),(Q24/P24^2)+(R24/P24),IF(OR(K24>0.7701,K24=0.7701),(Q24/P24^2)+R24,(Q24/P24^2)+(R24/P24))) -> 0.00073386897 | T24: =ROUND(EXP(-S24*O24*(1+0.8*S24*O24)),4) -> 0.9804
B25: 2BE | C25: VLSFO | D25: 4.382 | E25: 43.5 | F25: 98.211 | G25: Nil | H25: 0 | I25: =IF(F25="","",F25-H25) -> 98.211 | J25: =IF(F25="","",T25) -> 0.979 | K25: =K24 -> 0.935 | L25: =IF(F25="","",I25*J25) -> 96.148569 | M25: =IF(B25="","",ROUND(SUM(L25*K25),3)) -> 89.899 | N25: =(K25-0.0011)*L25 -> 89.793149 | O25: =E25-15 -> 28.5 | P25: =K25*1000 -> 935 | Q25: =IF(K25>0.8385,186.9696,IF(K25>0.7875,594.5418,IF(K25>0.77,2680.3206,346.4228))) -> 186.9696 | R25: =IF(K25>0.8385,0.4862,IF(K25>0.7875,0,IF(K25>0.77,-0.00336312,0.4388))) -> 0.4862 | S25: =IF(OR(K25>0.7876,K25=0.7876),(Q25/P25^2)+(R25/P25),IF(OR(K25>0.7701,K25=0.7701),(Q25/P25^2)+R25,(Q25/P25^2)+(R25/P25))) -> 0.00073386897 | T25: =ROUND(EXP(-S25*O25*(1+0.8*S25*O25)),4) -> 0.979
B26: 3BE | C26: VLSFO | D26: 4.323 | E26: 42.5 | F26: 50.739 | G26: Nil | H26: 0 | I26: =IF(F26="","",F26-H26) -> 50.739 | J26: =IF(F26="","",T26) -> 0.9797 | K26: =K25 -> 0.935 | L26: =IF(F26="","",I26*J26) -> 49.708998 | M26: =IF(B26="","",ROUND(SUM(L26*K26),3)) -> 46.478 | N26: =(K26-0.0011)*L26 -> 46.423234 | O26: =E26-15 -> 27.5 | P26: =K26*1000 -> 935 | Q26: =IF(K26>0.8385,186.9696,IF(K26>0.7875,594.5418,IF(K26>0.77,2680.3206,346.4228))) -> 186.9696 | R26: =IF(K26>0.8385,0.4862,IF(K26>0.7875,0,IF(K26>0.77,-0.00336312,0.4388))) -> 0.4862 | S26: =IF(OR(K26>0.7876,K26=0.7876),(Q26/P26^2)+(R26/P26),IF(OR(K26>0.7701,K26=0.7701),(Q26/P26^2)+R26,(Q26/P26^2)+(R26/P26))) -> 0.00073386897 | T26: =ROUND(EXP(-S26*O26*(1+0.8*S26*O26)),4) -> 0.9797
B27: 4 BE | C27: VLSFO | D27: 2.936 | E27: 41.5 | F27: 212.028 | G27: Nil | H27: 0 | I27: =IF(F27="","",F27-H27) -> 212.028 | J27: =IF(F27="","",T27) -> 0.9804 | K27: =K26 -> 0.935 | L27: =IF(F27="","",I27*J27) -> 207.87225 | M27: =IF(B27="","",ROUND(SUM(L27*K27),3)) -> 194.361 | N27: =(K27-0.0011)*L27 -> 194.1319 | O27: =E27-15 -> 26.5 | P27: =K27*1000 -> 935 | Q27: =IF(K27>0.8385,186.9696,IF(K27>0.7875,594.5418,IF(K27>0.77,2680.3206,346.4228))) -> 186.9696 | R27: =IF(K27>0.8385,0.4862,IF(K27>0.7875,0,IF(K27>0.77,-0.00336312,0.4388))) -> 0.4862 | S27: =IF(OR(K27>0.7876,K27=0.7876),(Q27/P27^2)+(R27/P27),IF(OR(K27>0.7701,K27=0.7701),(Q27/P27^2)+R27,(Q27/P27^2)+(R27/P27))) -> 0.00073386897 | T27: =ROUND(EXP(-S27*O27*(1+0.8*S27*O27)),4) -> 0.9804
F28: Total | I28: =SUM(I20:I27) -> 1132.541 | J28: =MEDIAN(J20:J27) -> 0.9799 | K28: =MEDIAN(K20:K27) -> 0.935 | L28: =SUM(L20:L27) -> 1109.7803 | M28: =ROUND(SUM(M20:M27),3) -> 1037.646 | N28: =SUM(N20:N27) -> 1036.4238
B31: AFTER RECEIVING | J31: FLOWMETER | K31: N/A | N31: m3
B32: Draft Fore: | C32: 2.5 | D32: m | E32: Draft Aft: | F32: 2.6 | G32: m | H32: List: | I32: 0 | J32: Trim Correction Applied: | L32: YES | M32: METRIC TONS
B33: Tank nº | C33: Grade | D33: Sounding / Ullage (m) | E33: Deg C | F33: Total Vol Observed (m3) | G33: Free Water | I33: Gross Obs Vol (m3) | J33: VCF TAB 54B | K33: Density (S.G.) at 15° C | L33: Gross Std Vol @15° C | M33: IN VAC | N33: IN AIR
G34: Dip | H34: Vol | X34: =SUM(L20:L27) -> 1109.7803
B35: =B20 -> 1BB | C35: =C20 -> VLSFO | D35: 2.951 | E35: =E20 -> 42 | F35: 204.691 | G35: Nil | H35: 0 | I35: =IF(F35="","",F35-H35) -> 204.691 | J35: =IF(F35="","",T35) -> 0.9801 | K35: =K20 -> 0.935 | L35: =IF(F35="","",I35*J35) -> 200.61765 | M35: =IF(B35="","",ROUND(SUM(L35*K35),3)) -> 187.578 | N35: =(K35-0.0011)*L35 -> 187.35682 | O35: =IF(E35="","",E35-15) -> 27 | P35: =K35*1000 -> 935 | Q35: =IF(K35>0.8385,186.9696,IF(K35>0.7875,594.5418,IF(K35>0.77,2680.3206,346.4228))) -> 186.9696 | R35: =IF(K35>0.8385,0.4862,IF(K35>0.7875,0,IF(K35>0.77,-0.00336312,0.4388))) -> 0.4862 | S35: =IF(OR(K35>0.7876,K35=0.7876),(Q35/P35^2)+(R35/P35),IF(OR(K35>0.7701,K35=0.7701),(Q35/P35^2)+R35,(Q35/P35^2)+(R35/P35))) -> 0.00073386897 | T35: =ROUND(EXP(-S35*O35*(1+0.8*S35*O35)),4) -> 0.9801 | W35: =I28-I43 -> 109.582 | X35: =SUM(L35:L42) -> 1002.3622 | Y35: =624.8*0.9799 -> 612.24152
B36: =B21 -> 2BB | C36: =C21 -> VLSFO | D36: 4.384 | E36: =E21 -> 44 | F36: 97.685 | G36: Nil | H36: 0 | I36: =IF(F36="","",F36-H36) -> 97.685 | J36: =IF(F36="","",T36) -> 0.9786 | K36: =K21 -> 0.935 | L36: =IF(F36="","",I36*J36) -> 95.594541 | M36: =IF(B36="","",ROUND(SUM(L36*K36),3)) -> 89.381 | N36: =(K36-0.0011)*L36 -> 89.275742 | O36: =E36-15 -> 29 | P36: =K36*1000 -> 935 | Q36: =IF(K36>0.8385,186.9696,IF(K36>0.7875,594.5418,IF(K36>0.77,2680.3206,346.4228))) -> 186.9696 | R36: =IF(K36>0.8385,0.4862,IF(K36>0.7875,0,IF(K36>0.77,-0.00336312,0.4388))) -> 0.4862 | S36: =IF(OR(K36>0.7876,K36=0.7876),(Q36/P36^2)+(R36/P36),IF(OR(K36>0.7701,K36=0.7701),(Q36/P36^2)+R36,(Q36/P36^2)+(R36/P36))) -> 0.00073386897 | T36: =ROUND(EXP(-S36*O36*(1+0.8*S36*O36)),4) -> 0.9786 | W36: =W35*0.9799 -> 107.3794 | X36: =X34-X35 -> 107.41812 | Y36: =Y35*0.9475 -> 580.09884
B37: =B22 -> 3BB | C37: =C22 -> VLSFO | D37: 4.339 | E37: =E22 -> 44 | F37: 50.341 | G37: Nil | H37: 0 | I37: =IF(F37="","",F37-H37) -> 50.341 | J37: =IF(F37="","",T37) -> 0.9786 | K37: =K22 -> 0.935 | L37: =IF(F37="","",I37*J37) -> 49.263703 | M37: =IF(B37="","",ROUND(SUM(L37*K37),3)) -> 46.062 | N37: =(K37-0.0011)*L37 -> 46.007372 | O37: =E37-15 -> 29 | P37: =K37*1000 -> 935 | Q37: =IF(K37>0.8385,186.9696,IF(K37>0.7875,594.5418,IF(K37>0.77,2680.3206,346.4228))) -> 186.9696 | R37: =IF(K37>0.8385,0.4862,IF(K37>0.7875,0,IF(K37>0.77,-0.00336312,0.4388))) -> 0.4862 | S37: =IF(OR(K37>0.7876,K37=0.7876),(Q37/P37^2)+(R37/P37),IF(OR(K37>0.7701,K37=0.7701),(Q37/P37^2)+R37,(Q37/P37^2)+(R37/P37))) -> 0.00073386897 | T37: =ROUND(EXP(-S37*O37*(1+0.8*S37*O37)),4) -> 0.9786 | W37: =W36*0.9475 -> 101.74198
B38: =B23 -> 4BB | C38: =C23 -> VLSFO | D38: 3.549 | E38: =E23 -> 42 | F38: 156.89 | G38: Nil | H38: 0 | I38: =IF(F38="","",F38-H38) -> 156.89 | J38: =IF(F38="","",T38) -> 0.9801 | K38: =K23 -> 0.935 | L38: =IF(F38="","",I38*J38) -> 153.76789 | M38: =IF(B38="","",ROUND(SUM(L38*K38),3)) -> 143.773 | N38: =(K38-0.0011)*L38 -> 143.60383 | O38: =E38-15 -> 27 | P38: =K38*1000 -> 935 | Q38: =IF(K38>0.8385,186.9696,IF(K38>0.7875,594.5418,IF(K38>0.77,2680.3206,346.4228))) -> 186.9696 | R38: =IF(K38>0.8385,0.4862,IF(K38>0.7875,0,IF(K38>0.77,-0.00336312,0.4388))) -> 0.4862 | S38: =IF(OR(K38>0.7876,K38=0.7876),(Q38/P38^2)+(R38/P38),IF(OR(K38>0.7701,K38=0.7701),(Q38/P38^2)+R38,(Q38/P38^2)+(R38/P38))) -> 0.00073386897 | T38: =ROUND(EXP(-S38*O38*(1+0.8*S38*O38)),4) -> 0.9801
B39: =B24 -> 1BE | C39: =C24 -> VLSFO | D39: 2.919 | E39: =E24 -> 41.5 | F39: 207.53 | G39: Nil | H39: 0 | I39: =IF(F39="","",F39-H39) -> 207.53 | J39: =IF(F39="","",T39) -> 0.9804 | K39: =K24 -> 0.935 | L39: =IF(F39="","",I39*J39) -> 203.46241 | M39: =IF(B39="","",ROUND(SUM(L39*K39),3)) -> 190.237 | N39: =(K39-0.0011)*L39 -> 190.01355 | O39: =E39-15 -> 26.5 | P39: =K39*1000 -> 935 | Q39: =IF(K39>0.8385,186.9696,IF(K39>0.7875,594.5418,IF(K39>0.77,2680.3206,346.4228))) -> 186.9696 | R39: =IF(K39>0.8385,0.4862,IF(K39>0.7875,0,IF(K39>0.77,-0.00336312,0.4388))) -> 0.4862 | S39: =IF(OR(K39>0.7876,K39=0.7876),(Q39/P39^2)+(R39/P39),IF(OR(K39>0.7701,K39=0.7701),(Q39/P39^2)+R39,(Q39/P39^2)+(R39/P39))) -> 0.00073386897 | T39: =ROUND(EXP(-S39*O39*(1+0.8*S39*O39)),4) -> 0.9804
B40: =B25 -> 2BE | C40: =C25 -> VLSFO | D40: 4.389 | E40: =E25 -> 43.5 | F40: 97.572 | G40: Nil | H40: 0 | I40: =IF(F40="","",F40-H40) -> 97.572 | J40: =IF(F40="","",T40) -> 0.979 | K40: =K25 -> 0.935 | L40: =IF(F40="","",I40*J40) -> 95.522988 | M40: =IF(B40="","",ROUND(SUM(L40*K40),3)) -> 89.314 | N40: =(K40-0.0011)*L40 -> 89.208918 | O40: =E40-15 -> 28.5 | P40: =K40*1000 -> 935 | Q40: =IF(K40>0.8385,186.9696,IF(K40>0.7875,594.5418,IF(K40>0.77,2680.3206,346.4228))) -> 186.9696 | R40: =IF(K40>0.8385,0.4862,IF(K40>0.7875,0,IF(K40>0.77,-0.00336312,0.4388))) -> 0.4862 | S40: =IF(OR(K40>0.7876,K40=0.7876),(Q40/P40^2)+(R40/P40),IF(OR(K40>0.7701,K40=0.7701),(Q40/P40^2)+R40,(Q40/P40^2)+(R40/P40))) -> 0.00073386897 | T40: =ROUND(EXP(-S40*O40*(1+0.8*S40*O40)),4) -> 0.979
B41: =B26 -> 3BE | C41: =C26 -> VLSFO | D41: 4.331 | E41: =E26 -> 42.5 | F41: 50.411 | G41: Nil | H41: 0 | I41: =IF(F41="","",F41-H41) -> 50.411 | J41: =IF(F41="","",T41) -> 0.9797 | K41: =K26 -> 0.935 | L41: =IF(F41="","",I41*J41) -> 49.387657 | M41: =IF(B41="","",ROUND(SUM(L41*K41),3)) -> 46.177 | N41: =(K41-0.0011)*L41 -> 46.123133 | O41: =E41-15 -> 27.5 | P41: =K41*1000 -> 935 | Q41: =IF(K41>0.8385,186.9696,IF(K41>0.7875,594.5418,IF(K41>0.77,2680.3206,346.4228))) -> 186.9696 | R41: =IF(K41>0.8385,0.4862,IF(K41>0.7875,0,IF(K41>0.77,-0.00336312,0.4388))) -> 0.4862 | S41: =IF(OR(K41>0.7876,K41=0.7876),(Q41/P41^2)+(R41/P41),IF(OR(K41>0.7701,K41=0.7701),(Q41/P41^2)+R41,(Q41/P41^2)+(R41/P41))) -> 0.00073386897 | T41: =ROUND(EXP(-S41*O41*(1+0.8*S41*O41)),4) -> 0.9797
B42: =B27 -> 4 BE | C42: =C27 -> VLSFO | D42: 3.555 | E42: =E27 -> 41.5 | F42: 157.839 | G42: Nil | H42: 0 | I42: =IF(F42="","",F42-H42) -> 157.839 | J42: =IF(F42="","",T42) -> 0.9804 | K42: =K27 -> 0.935 | L42: =IF(F42="","",I42*J42) -> 154.74536 | M42: =IF(B42="","",ROUND(SUM(L42*K42),3)) -> 144.687 | N42: =(K42-0.0011)*L42 -> 144.51669 | O42: =E42-15 -> 26.5 | P42: =K42*1000 -> 935 | Q42: =IF(K42>0.8385,186.9696,IF(K42>0.7875,594.5418,IF(K42>0.77,2680.3206,346.4228))) -> 186.9696 | R42: =IF(K42>0.8385,0.4862,IF(K42>0.7875,0,IF(K42>0.77,-0.00336312,0.4388))) -> 0.4862 | S42: =IF(OR(K42>0.7876,K42=0.7876),(Q42/P42^2)+(R42/P42),IF(OR(K42>0.7701,K42=0.7701),(Q42/P42^2)+R42,(Q42/P42^2)+(R42/P42))) -> 0.00073386897 | T42: =ROUND(EXP(-S42*O42*(1+0.8*S42*O42)),4) -> 0.9804
F43: Total | I43: =SUM(I35:I42) -> 1022.959 | J43: =MEDIAN(J35:J42) -> 0.9799 | K43: =MEDIAN(K35:K42) -> 0.935 | L43: =SUM(L35:L42) -> 1002.3622 | M43: =ROUND(SUM(M35:M42),3) -> 937.209 | N43: =SUM(N35:N42) -> 936.10605
B45: Density @ 15 Deg C as per BDN - Bunker Deliver Notice | E45: Density @ 20 Deg C as per BDN - Bunker Deliver Notice | I45: TOTAL QTY TRANSFERRED - ULLAGE/SOUNDING | M45: =N28-N43 -> 100.31778 | N45: MT
B47: 0.935 | E47: 0.9317 | I47: TOTAL QTY TRANSFERRED - FLOWMETER | M47: N/A | N47: MT
B50: Flowmeter type: | D50: N/A
B51: Calibration Date: | D51: N/A
B52: Seal: | D52: N/A
B54: Thermometer Type: | D54: GLASS / MERCURY
...

Sheet Time Log
F2: MARINE SURVEYORS & CONSULTANTS
G3: Av. Ana Costa, 433 sl 184 - Santos /BR
F4: surveyors@naabsa.com | Naabsa.com | TEL: 55 13 3394-0655
A7: TIME LOG
A9: Name of Vessel: | C9: ='Vessel Ullage'!D8 -> CAPE KENNEDY | E9: Grade of Fuel Ordered: | G9: ='Vessel Ullage'!J8 -> VLSFO 0.5% S
E10: Location of Survey: | G10: ='Vessel Ullage'!J9 -> Paranagua Port - Shed 212
A11: Name of Barges : | C11: ='Vessel Ullage'!D10 -> OMS V | E11: Date of Survey: | G11: ='Vessel Ullage'!J10 -> April 14th, 2026
E12: Time: | G12: ='Vessel Ullage'!J11 -> 16:50 x 22:00 h/LT
A15: Operation | D15: Date | E15: Times
A16: POB for berthing | D16: 46126 | E16: 0.53472222 | F16: -
A17: Gangway down | D17: 46126 | E17: 0.59375 | F17: - | Y17: 21418555
A18: Awaiting barge | D18: 46126
D19: 46126
A20: Bunker Barge arrived | D20: 46126 | E20: 0.73611111 | F20: -
A21: Surveyor onboard | D21: 46126 | E21: 0.70138889 | F21: -
A22: Meeting between C/E and surveyor | D22: 46126 | E22: 0.70833333 | F22: -
A23: Initial Soundings/Ullage - Vessel | D23: 46126 | E23: 0.71527778 | F23: 0.73958333
A24: All fast / Barge ready | D24: 46126 | E24: 0.75 | F24: -
A25: Initial Soundings/Ullage - Barge | D25: 46126 | E25: 0.75694444 | F25: 0.77083333
A26: Hose Connected | D26: 46126 | E26: 0.80555556 | F26: -
A27: Bunkering operation | D27: 46126 | E27: 0.84375 | F27: 0.87847222
A28: Final Soundings/Ullage - Barge | D28: 46126 | E28: 0.88194444 | F28: 0.88888889
A29: Final Soundings/Ullage - Vessel | D29: 46126 | E29: 0.89236111 | F29: 0.89583333
A30: Calculation | D30: 46126 | E30: 0.89930556 | F30: 0.90277778
A31: Documents signed | D31: 46126 | E31: 0.91319444 | F31: -
A32: Hose disconnected | D32: 46126 | E32: 0.90972222 | F32: -
A33: Surveyor off board | D33: 46126 | E33: 0.91666667 | F33: -
A36: Stoppages/Delays
A37: NO DELAYS
A46: Remark:
A57: CHIEF ENGINEER: | C57: ='Vessel Ullage'!E74 -> Geraimovych, Volodymyr | G57: SURVEYOR: | I57: ='Vessel Ullage'!L74 -> Lara, Ernesto

Sheet Sample Report
G2: MARINE SURVEYORS & CONSULTANTS
G3: Av. Ana Costa, 433 sl 184 - Santos /BR
F4: surveyors@naabsa.com | Naabsa.com | TEL: 55 13 3394-0655
A9: SAMPLE REPORT
A11: Name of Vessel: | C11: ='Vessel Ullage'!D8 -> CAPE KENNEDY | E11: Grade of Fuel Ordered: | G11: ='Vessel Ullage'!J8 -> VLSFO 0.5% S
E12: Location of Survey: | G12: ='Vessel Ullage'!J9 -> Paranagua Port - Shed 212
A13: Name of Barges : | C13: ='Vessel Ullage'!D10 -> OMS V | E13: Date of Survey: | G13: ='Vessel Ullage'!J10 -> April 14th, 2026
E14: Time: | G14: ='Vessel Ullage'!J11 -> 16:50 x 22:00 h/LT
A17: SAMPLES WERE TAKEN DURING BUNKERING
A19: Name of barge | D19: ='Vessel Ullage'!D10 -> OMS V
A20: Grade | D20: ='Vessel Ullage'!J8 -> VLSFO 0.5% S
A21: Tank number | D21: HFO 1P
A22: Sampling Method | D22: DRIPPING
A23: Sampling Point | D23: SHIP MANIFOLD | F23: SHIP MANIFOLD
A24: Quantity of Sample | D24: 5 x 0,5 L | F24: 4 x 0,5 L
A25: SAMPLES | D25: VESSEL | F25: BARGE
A26: Retained by Chife Engineer | D26: A5510352 | F26: 0026339
A27: Retained by Supplier`s Representative | D27: A5510351 | F27: 0026346
A28: Laboratory | D28: A5510350 | F28: 0026311
A29: Marpol Sample | D29: A5510353 | F29: 0026303
A30: Surveyor Samples | D30: A5510360 | F30: -
F31: -
F32: -
A35: Remarks(IF ANY)
A40: CHIEF ENGINEER: | C40: ='Vessel Ullage'!E74 -> Geraimovych, Volodymyr | G40: SURVEYOR: | I40: ='Vessel Ullage'!L74 -> Lara, Ernesto

Sheet Letter of Protest (2)
G2: MARINE SURVEYORS & CONSULTANTS
H3: Av. Ana Costa, 433 sl 184 - Santos /BR
G4: surveyors@naabsa.com | Naabsa.com | TEL: 55 13 3394-0655
A8: Name of Vessel: | C8: ='Vessel Ullage'!D8 -> CAPE KENNEDY | F8: Grade of Fuel Ordered: | H8: ='Sounding Barge'!J9 -> VLSFO 0.5% S
F9: Location of Survey: | H9: ='Vessel Ullage'!J9 -> Paranagua Port - Shed 212
A10: Name of Barges : | C10: ='Vessel Ullage'!D10 -> OMS V | F10: Date of Survey: | H10: ='Vessel Ullage'!J10 -> April 14th, 2026
F11: Time: | H11: ='Vessel Ullage'!J11 -> 16:50 x 22:00 h/LT
A13: To: Supplier or representative
A15: C/c: CHIEF ENGINEER
F18: LETTER OF PROTEST
A23: Vessel : | B23: ='Vessel Ullage'!D8 -> CAPE KENNEDY | F23: Date : | G23: ='Vessel Ullage'!J10 -> April 14th, 2026
A25: Location : | B25: ='Vessel Ullage'!J9 -> Paranagua Port - Shed 212 | F25: Product : | G25: ='Vessel Ullage'!J8 -> VLSFO 0.5% S
A28: We have been appointed as Marine Surveyors to act on behalf of our Principals and the following
A29: figures is brought to your attention to the differences bellow:
F32: difference
D33: BDN | E33: NAABSA | F33: MT | G33: %
D34: ='Vessel Ullage'!M58 -> 100.542 | E34: ='Vessel Ullage'!M59 -> 100.23167 | F34: ='Vessel Ullage'!M60 -> -0.31033085 | G34: ='Vessel Ullage'!M61 -> -0.30961358
A36: We hereby reserve the right of our Principals to make reference to the above at a later date.
A43: Signed for receipt:
A45: VESSEL/BARGE REPRESENTATIVE : | G45: SURVEYOR: | I45: ='Vessel Ullage'!L74 -> Lara, Ernesto
A46: STAMPED AND SIGNED

Sheet VacuoAr
A1: Density at 15C | B1: FCW Vacuo-Ar
A2: 0.5 | B2: 0.99775
A3: 0.5191 | B3: 0.99775
A4: 0.5192 | B4: 0.99785
A5: 0.5421 | B5: 0.99785
A6: 0.5422 | B6: 0.99795
A7: 0.5673 | B7: 0.99795
A8: 0.5674 | B8: 0.99805
A9: 0.595 | B9: 0.99805
A10: 0.5951 | B10: 0.99815
A11: 0.6255 | B11: 0.99815
A12: 0.6256 | B12: 0.99825
A13: 0.6593 | B13: 0.99825
... A29: 1.1 | B29: 0.99905
