Workbook

Sheet Vessel Ullage
G2: MARINE SURVEYORS & CONSULTANTS
G3: Av. Ana Costa, 433 suite 184 - Santos /BR
G4: surveyors@naabsa.com | Naabsa.com | TEL: 55 13 3394-0655
A6: VESSEL´S SOUNDING/ULLAGE REPORT
A8: Name of Vessel: | C8: Elite Star | G8: Grade of Fuel Ordered: | I8: VLSFO
G9: Location of Survey: | I9: Santos Port - Tiplam Terminal
A10: Name of Barges : | C10: SC 60 | G10: Survey Start: | I10: February 19th, 2026 - 08:00 lt
G11: Survey Completed: | I11: February 19th, 2026 - 21:00h lt
A17: BEFORE BUNKERING
A18: Draft Fore: | B18: 2.8 | C18: m | D18: Draft Aft: | E18: 6.48 | F18: m | G18: List: | H18: 0 | I18: Trim Correction Applied: | K18: Yes | L18: METRIC TONS
A19: Tank nº | B19: Grade | C19: Sounding/ Ullage (m) | D19: Deg °C | E19: Total Vol Observed (m3) | F19: Free Water | H19: Gross Obs Vol (m3) | I19: VCF TAB 54B | J19: Density (S.G.) at 15° C | K19: Gross Std Vol @15° C | L19: IN VAC | M19: IN AIR
F20: Dip | G20: Vol
A21: FO 1C | B21: VLSFO | C21: S 00,06 | D21: 37 | E21: 3.942 | F21: Nil | G21: 0 | H21: =IF(E21="","",E21-G21) -> 3.942 | I21: =IF(E21="","",S21) -> 0.9845 | J21: 0.9705 | K21: =IF(E21="","",H21*I21) -> 3.880899 | L21: =IF(A21="","",ROUND(SUM(K21*J21),3)) -> 3.766 | M21: =(J21-0.0011)*K21 -> 3.7621435 | N21: =D21-15 -> 22 | O21: =J21*1000 -> 970.5 | P21: =IF(J21>0.8385,186.9696,IF(J21>0.7875,594.5418,IF(J21>0.77,2680.3206,346.4228))) -> 186.9696 | Q21: =IF(J21>0.8385,0.4862,IF(J21>0.7875,0,IF(J21>0.77,-0.00336312,0.4388))) -> 0.4862 | R21: =IF(OR(J21>0.7876,J21=0.7876),(P21/O21^2)+(Q21/O21),IF(OR(J21>0.7701,J21=0.7701),(P21/O21^2)+Q21,(P21/O21^2)+(Q21/O21))) -> 0.00069948775 | S21: =ROUND(EXP(-R21*N21*(1+0.8*R21*N21)),4) -> 0.9845
A22: FO 2C | B22: VLSFO | C22: U 19,27 | D22: 43 | E22: 141.336 | F22: Nil | G22: 0 | H22: =IF(E22="","",E22-G22) -> 141.336 | I22: =IF(E22="","",S22) -> 0.9791 | J22: 0.9287 | K22: =IF(E22="","",H22*I22) -> 138.38208 | L22: =IF(A22="","",ROUND(SUM(K22*J22),3)) -> 128.515 | M22: =(J22-0.0011)*K22 -> 128.36322 | N22: =D22-15 -> 28 | O22: =J22*1000 -> 928.7 | P22: =IF(J22>0.8385,186.9696,IF(J22>0.7875,594.5418,IF(J22>0.77,2680.3206,346.4228))) -> 186.9696 | Q22: =IF(J22>0.8385,0.4862,IF(J22>0.7875,0,IF(J22>0.77,-0.00336312,0.4388))) -> 0.4862 | R22: =IF(OR(J22>0.7876,J22=0.7876),(P22/O22^2)+(Q22/O22),IF(OR(J22>0.7701,J22=0.7701),(P22/O22^2)+Q22,(P22/O22^2)+(Q22/O22))) -> 0.00074030796 | S22: =ROUND(EXP(-R22*N22*(1+0.8*R22*N22)),4) -> 0.9791
A23: AFT-S | B23: VLSFO | C23: U 02,69 | D23: 40 | E23: 238.365 | F23: Nil | G23: 0 | H23: =IF(E23="","",E23-G23) -> 238.365 | I23: =IF(E23="","",S23) -> 0.9814 | J23: 0.9287 | K23: =IF(E23="","",H23*I23) -> 233.93141 | L23: =IF(A23="","",ROUND(SUM(K23*J23),3)) -> 217.252 | M23: =(J23-0.0011)*K23 -> 216.99478 | N23: =D23-15 -> 25 | O23: =J23*1000 -> 928.7 | P23: =IF(J23>0.8385,186.9696,IF(J23>0.7875,594.5418,IF(J23>0.77,2680.3206,346.4228))) -> 186.9696 | Q23: =IF(J23>0.8385,0.4862,IF(J23>0.7875,0,IF(J23>0.77,-0.00336312,0.4388))) -> 0.4862 | R23: =IF(OR(J23>0.7876,J23=0.7876),(P23/O23^2)+(Q23/O23),IF(OR(J23>0.7701,J23=0.7701),(P23/O23^2)+Q23,(P23/O23^2)+(Q23/O23))) -> 0.00074030796 | S23: =ROUND(EXP(-R23*N23*(1+0.8*R23*N23)),4) -> 0.9814
A24: FO SETT | B24: VLSFO | C24: GAUGE | D24: 72 | E24: 8.3 | F24: Nil | G24: 0 | H24: =IF(E24="","",E24-G24) -> 8.3 | I24: =IF(E24="","",S24) -> 0.9573 | J24: 0.9287 | K24: =IF(E24="","",H24*I24) -> 7.94559 | L24: =IF(A24="","",ROUND(SUM(K24*J24),3)) -> 7.379 | M24: =(J24-0.0011)*K24 -> 7.3703293 | N24: =D24-15 -> 57 | O24: =J24*1000 -> 928.7 | P24: =IF(J24>0.8385,186.9696,IF(J24>0.7875,594.5418,IF(J24>0.77,2680.3206,346.4228))) -> 186.9696 | Q24: =IF(J24>0.8385,0.4862,IF(J24>0.7875,0,IF(J24>0.77,-0.00336312,0.4388))) -> 0.4862 | R24: =IF(OR(J24>0.7876,J24=0.7876),(P24/O24^2)+(Q24/O24),IF(OR(J24>0.7701,J24=0.7701),(P24/O24^2)+Q24,(P24/O24^2)+(Q24/O24))) -> 0.00074030796 | S24: =ROUND(EXP(-R24*N24*(1+0.8*R24*N24)),4) -> 0.9573
A25: FO SERV | B25: VLSFO | C25: GAUGE | D25: 88 | E25: 10 | F25: Nil | G25: 0 | H25: =IF(E25="","",E25-G25) -> 10 | I25: =IF(E25="","",S25) -> 0.9452 | J25: 0.9287 | K25: =IF(E25="","",H25*I25) -> 9.452 | L25: =IF(A25="","",ROUND(SUM(K25*J25),3)) -> 8.778 | M25: =(J25-0.0011)*K25 -> 8.7676752 | N25: =D25-15 -> 73 | O25: =J25*1000 -> 928.7 | P25: =IF(J25>0.8385,186.9696,IF(J25>0.7875,594.5418,IF(J25>0.77,2680.3206,346.4228))) -> 186.9696 | Q25: =IF(J25>0.8385,0.4862,IF(J25>0.7875,0,IF(J25>0.77,-0.00336312,0.4388))) -> 0.4862 | R25: =IF(OR(J25>0.7876,J25=0.7876),(P25/O25^2)+(Q25/O25),IF(OR(J25>0.7701,J25=0.7701),(P25/O25^2)+Q25,(P25/O25^2)+(Q25/O25))) -> 0.00074030796 | S25: =ROUND(EXP(-R25*N25*(1+0.8*R25*N25)),4) -> 0.9452
A26: OVERFLOW | B26: VLSFO | C26: S 00,16 | D26: 40 | E26: 0.3 | F26: Nil | G26: 0 | H26: =IF(E26="","",E26-G26) -> 0.3 | I26: =IF(E26="","",S26) -> 0.9814 | J26: 0.9287 | K26: =IF(E26="","",H26*I26) -> 0.29442 | L26: =IF(A26="","",ROUND(SUM(K26*J26),3)) -> 0.273 | M26: =(J26-0.0011)*K26 -> 0.27310399 | N26: =D26-15 -> 25 | O26: =J26*1000 -> 928.7 | P26: =IF(J26>0.8385,186.9696,IF(J26>0.7875,594.5418,IF(J26>0.77,2680.3206,346.4228))) -> 186.9696 | Q26: =IF(J26>0.8385,0.4862,IF(J26>0.7875,0,IF(J26>0.77,-0.00336312,0.4388))) -> 0.4862 | R26: =IF(OR(J26>0.7876,J26=0.7876),(P26/O26^2)+(Q26/O26),IF(OR(J26>0.7701,J26=0.7701),(P26/O26^2)+Q26,(P26/O26^2)+(Q26/O26))) -> 0.00074030796 | S26: =ROUND(EXP(-R26*N26*(1+0.8*R26*N26)),4) -> 0.9814
A27: 7 | B27: VLSFO | C27: 0 | D27: 0 | E27: 0 | F27: Nil | G27: 0 | H27: =IF(E27="","",E27-G27) -> 0 | I27: =IF(E27="","",S27) -> 1.0115 | J27: 0.9 | K27: =IF(E27="","",H27*I27) -> 0 | L27: =IF(A27="","",ROUND(SUM(K27*J27),3)) -> 0 | M27: =(J27-0.0011)*K27 -> 0 | N27: =D27-15 -> -15 | O27: =J27*1000 -> 900 | P27: =IF(J27>0.8385,186.9696,IF(J27>0.7875,594.5418,IF(J27>0.77,2680.3206,346.4228))) -> 186.9696 | Q27: =IF(J27>0.8385,0.4862,IF(J27>0.7875,0,IF(J27>0.77,-0.00336312,0.4388))) -> 0.4862 | R27: =IF(OR(J27>0.7876,J27=0.7876),(P27/O27^2)+(Q27/O27),IF(OR(J27>0.7701,J27=0.7701),(P27/O27^2)+Q27,(P27/O27^2)+(Q27/O27))) -> 0.00077104889 | S27: =ROUND(EXP(-R27*N27*(1+0.8*R27*N27)),4) -> 1.0115
A28: 8 | B28: VLSFO | C28: 0 | D28: 0 | E28: 0 | F28: Nil | G28: 0 | H28: =IF(E28="","",E28-G28) -> 0 | I28: =IF(E28="","",S28) -> 1.0115 | J28: 0.9 | K28: =IF(E28="","",H28*I28) -> 0 | L28: =IF(A28="","",ROUND(SUM(K28*J28),3)) -> 0 | M28: =(J28-0.0011)*K28 -> 0 | N28: =D28-15 -> -15 | O28: =J28*1000 -> 900 | P28: =IF(J28>0.8385,186.9696,IF(J28>0.7875,594.5418,IF(J28>0.77,2680.3206,346.4228))) -> 186.9696 | Q28: =IF(J28>0.8385,0.4862,IF(J28>0.7875,0,IF(J28>0.77,-0.00336312,0.4388))) -> 0.4862 | R28: =IF(OR(J28>0.7876,J28=0.7876),(P28/O28^2)+(Q28/O28),IF(OR(J28>0.7701,J28=0.7701),(P28/O28^2)+Q28,(P28/O28^2)+(Q28/O28))) -> 0.00077104889 | S28: =ROUND(EXP(-R28*N28*(1+0.8*R28*N28)),4) -> 1.0115
A29: 9 | B29: VLSFO | C29: 0 | D29: 0 | E29: 0 | F29: Nil | G29: 0 | H29: =IF(E29="","",E29-G29) -> 0 | I29: =IF(E29="","",S29) -> 1.0115 | J29: 0.9 | K29: =IF(E29="","",H29*I29) -> 0 | L29: =IF(A29="","",ROUND(SUM(K29*J29),3)) -> 0 | M29: =(J29-0.0011)*K29 -> 0 | N29: =D29-15 -> -15 | O29: =J29*1000 -> 900 | P29: =IF(J29>0.8385,186.9696,IF(J29>0.7875,594.5418,IF(J29>0.77,2680.3206,346.4228))) -> 186.9696 | Q29: =IF(J29>0.8385,0.4862,IF(J29>0.7875,0,IF(J29>0.77,-0.00336312,0.4388))) -> 0.4862 | R29: =IF(OR(J29>0.7876,J29=0.7876),(P29/O29^2)+(Q29/O29),IF(OR(J29>0.7701,J29=0.7701),(P29/O29^2)+Q29,(P29/O29^2)+(Q29/O29))) -> 0.00077104889 | S29: =ROUND(EXP(-R29*N29*(1+0.8*R29*N29)),4) -> 1.0115
A30: 10 | B30: VLSFO | C30: 0 | D30: 0 | E30: 0 | F30: Nil | G30: 0 | H30: =IF(E30="","",E30-G30) -> 0 | I30: =IF(E30="","",S30) -> 1.0115 | J30: 0.9 | K30: =IF(E30="","",H30*I30) -> 0 | L30: =IF(A30="","",ROUND(SUM(K30*J30),3)) -> 0 | M30: =(J30-0.0011)*K30 -> 0 | N30: =D30-15 -> -15 | O30: =J30*1000 -> 900 | P30: =IF(J30>0.8385,186.9696,IF(J30>0.7875,594.5418,IF(J30>0.77,2680.3206,346.4228))) -> 186.9696 | Q30: =IF(J30>0.8385,0.4862,IF(J30>0.7875,0,IF(J30>0.77,-0.00336312,0.4388))) -> 0.4862 | R30: =IF(OR(J30>0.7876,J30=0.7876),(P30/O30^2)+(Q30/O30),IF(OR(J30>0.7701,J30=0.7701),(P30/O30^2)+Q30,(P30/O30^2)+(Q30/O30))) -> 0.00077104889 | S30: =ROUND(EXP(-R30*N30*(1+0.8*R30*N30)),4) -> 1.0115
A31: 11 | B31: VLSFO | C31: 0 | D31: 0 | E31: 0 | F31: Nil | G31: 0 | H31: =IF(E31="","",E31-G31) -> 0 | I31: =IF(E31="","",S31) -> 1.0115 | J31: 0.9 | K31: =IF(E31="","",H31*I31) -> 0 | L31: =IF(A31="","",ROUND(SUM(K31*J31),3)) -> 0 | M31: =(J31-0.0011)*K31 -> 0 | N31: =D31-15 -> -15 | O31: =J31*1000 -> 900 | P31: =IF(J31>0.8385,186.9696,IF(J31>0.7875,594.5418,IF(J31>0.77,2680.3206,346.4228))) -> 186.9696 | Q31: =IF(J31>0.8385,0.4862,IF(J31>0.7875,0,IF(J31>0.77,-0.00336312,0.4388))) -> 0.4862 | R31: =IF(OR(J31>0.7876,J31=0.7876),(P31/O31^2)+(Q31/O31),IF(OR(J31>0.7701,J31=0.7701),(P31/O31^2)+Q31,(P31/O31^2)+(Q31/O31))) -> 0.00077104889 | S31: =ROUND(EXP(-R31*N31*(1+0.8*R31*N31)),4) -> 1.0115
A32: 12 | B32: VLSFO | C32: 0 | D32: 0 | E32: 0 | F32: Nil | G32: 0 | H32: =IF(E32="","",E32-G32) -> 0 | I32: =IF(E32="","",S32) -> 1.0115 | J32: 0.9 | K32: =IF(E32="","",H32*I32) -> 0 | L32: =IF(A32="","",ROUND(SUM(K32*J32),3)) -> 0 | M32: =(J32-0.0011)*K32 -> 0 | N32: =D32-15 -> -15 | O32: =J32*1000 -> 900 | P32: =IF(J32>0.8385,186.9696,IF(J32>0.7875,594.5418,IF(J32>0.77,2680.3206,346.4228))) -> 186.9696 | Q32: =IF(J32>0.8385,0.4862,IF(J32>0.7875,0,IF(J32>0.77,-0.00336312,0.4388))) -> 0.4862 | R32: =IF(OR(J32>0.7876,J32=0.7876),(P32/O32^2)+(Q32/O32),IF(OR(J32>0.7701,J32=0.7701),(P32/O32^2)+Q32,(P32/O32^2)+(Q32/O32))) -> 0.00077104889 | S32: =ROUND(EXP(-R32*N32*(1+0.8*R32*N32)),4) -> 1.0115
A33: TOTAL | H33: =SUM(H21:H32) -> 402.243 | K33: =SUM(K21:K32) -> 393.8864 | L33: =SUM(L21:L32) -> 365.963 | M33: =SUM(M21:M32) -> 365.53124 | N33: =SUM(N21:N32) -> 140
J35: LOG BOOK | K35: 355.5 | L35: Dif | M35: =M33-K35 -> 10.031244
A37: AFTER BUNKERING
A38: Draft Fore: | B38: 2.4 | C38: m | D38: Draft Aft: | E38: 6.22 | F38: m | G38: List: | H38: 0 | I38: Trim Correction Applied: | K38: Yes | L38: METRIC TONS
A39: Tank nº | B39: Grade | C39: Sounding/ Ullage (m) | D39: Deg C | E39: Total Vol Observed (m3) | F39: Free Water | H39: Gross Obs Vol (m3) | I39: VCF TAB 54B | J39: Density (S.G.) at 15° C | K39: Gross Std Vol @15° C | L39: IN VAC | M39: IN AIR
F40: Dip | G40: Vol
A41: =A21 -> FO 1C | B41: VLSFO | C41: U 18,60 | D41: 40 | E41: 977.001 | F41: Nil | G41: 0 | H41: =IF(E41="","",E41-G41) -> 977.001 | I41: =IF(E41="","",S41) -> 0.9817 | J41: 0.941 | K41: =IF(E41="","",H41*I41) -> 959.12188 | L41: =IF(A41="","",ROUND(SUM(K41*J41),3)) -> 902.534 | M41: =(J41-0.0011)*K41 -> 901.47866 | N41: =D41-15 -> 25 | O41: =J41*1000 -> 941 | P41: =IF(J41>0.8385,186.9696,IF(J41>0.7875,594.5418,IF(J41>0.77,2680.3206,346.4228))) -> 186.9696 | Q41: =IF(J41>0.8385,0.4862,IF(J41>0.7875,0,IF(J41>0.77,-0.00336312,0.4388))) -> 0.4862 | R41: =IF(OR(J41>0.7876,J41=0.7876),(P41/O41^2)+(Q41/O41),IF(OR(J41>0.7701,J41=0.7701),(P41/O41^2)+Q41,(P41/O41^2)+(Q41/O41))) -> 0.0007278347 | S41: =ROUND(EXP(-R41*N41*(1+0.8*R41*N41)),4) -> 0.9817
A42: =A22 -> FO 2C | B42: VLSFO | C42: U 19,27 | D42: 43 | E42: 145.936 | F42: Nil | G42: 0 | H42: =IF(E42="","",E42-G42) -> 145.936 | I42: =IF(E42="","",S42) -> 0.9791 | J42: 0.9287 | K42: =IF(E42="","",H42*I42) -> 142.88594 | L42: =IF(A42="","",ROUND(SUM(K42*J42),3)) -> 132.698 | M42: =(J42-0.0011)*K42 -> 132.541 | N42: =D42-15 -> 28 | O42: =J42*1000 -> 928.7 | P42: =IF(J42>0.8385,186.9696,IF(J42>0.7875,594.5418,IF(J42>0.77,2680.3206,346.4228))) -> 186.9696 | Q42: =IF(J42>0.8385,0.4862,IF(J42>0.7875,0,IF(J42>0.77,-0.00336312,0.4388))) -> 0.4862 | R42: =IF(OR(J42>0.7876,J42=0.7876),(P42/O42^2)+(Q42/O42),IF(OR(J42>0.7701,J42=0.7701),(P42/O42^2)+Q42,(P42/O42^2)+(Q42/O42))) -> 0.00074030796 | S42: =ROUND(EXP(-R42*N42*(1+0.8*R42*N42)),4) -> 0.9791
A43: =A23 -> AFT-S | B43: VLSFO | C43: U 02,69 | D43: 40 | E43: 238.365 | F43: Nil | G43: 0 | H43: =IF(E43="","",E43-G43) -> 238.365 | I43: =IF(E43="","",S43) -> 0.9814 | J43: 0.9287 | K43: =IF(E43="","",H43*I43) -> 233.93141 | L43: =IF(A43="","",ROUND(SUM(K43*J43),3)) -> 217.252 | M43: =(J43-0.0011)*K43 -> 216.99478 | N43: =D43-15 -> 25 | O43: =J43*1000 -> 928.7 | P43: =IF(J43>0.8385,186.9696,IF(J43>0.7875,594.5418,IF(J43>0.77,2680.3206,346.4228))) -> 186.9696 | Q43: =IF(J43>0.8385,0.4862,IF(J43>0.7875,0,IF(J43>0.77,-0.00336312,0.4388))) -> 0.4862 | R43: =IF(OR(J43>0.7876,J43=0.7876),(P43/O43^2)+(Q43/O43),IF(OR(J43>0.7701,J43=0.7701),(P43/O43^2)+Q43,(P43/O43^2)+(Q43/O43))) -> 0.00074030796 | S43: =ROUND(EXP(-R43*N43*(1+0.8*R43*N43)),4) -> 0.9814
A44: =A24 -> FO SETT | B44: VLSFO | C44: GAUGE | D44: 72 | E44: 8.3 | F44: Nil | G44: 0 | H44: =IF(E44="","",E44-G44) -> 8.3 | I44: =IF(E44="","",S44) -> 0.9573 | J44: 0.9287 | K44: =IF(E44="","",H44*I44) -> 7.94559 | L44: =IF(A44="","",ROUND(SUM(K44*J44),3)) -> 7.379 | M44: =(J44-0.0011)*K44 -> 7.3703293 | N44: =D44-15 -> 57 | O44: =J44*1000 -> 928.7 | P44: =IF(J44>0.8385,186.9696,IF(J44>0.7875,594.5418,IF(J44>0.77,2680.3206,346.4228))) -> 186.9696 | Q44: =IF(J44>0.8385,0.4862,IF(J44>0.7875,0,IF(J44>0.77,-0.00336312,0.4388))) -> 0.4862 | R44: =IF(OR(J44>0.7876,J44=0.7876),(P44/O44^2)+(Q44/O44),IF(OR(J44>0.7701,J44=0.7701),(P44/O44^2)+Q44,(P44/O44^2)+(Q44/O44))) -> 0.00074030796 | S44: =ROUND(EXP(-R44*N44*(1+0.8*R44*N44)),4) -> 0.9573
A45: =A25 -> FO SERV | B45: VLSFO | C45: GAUGE | D45: 88 | E45: 8 | F45: Nil | G45: 0 | H45: =IF(E45="","",E45-G45) -> 8 | I45: =IF(E45="","",S45) -> 0.9452 | J45: 0.9287 | K45: =IF(E45="","",H45*I45) -> 7.5616 | L45: =IF(A45="","",ROUND(SUM(K45*J45),3)) -> 7.022 | M45: =(J45-0.0011)*K45 -> 7.0141402 | N45: =D45-15 -> 73 | O45: =J45*1000 -> 928.7 | P45: =IF(J45>0.8385,186.9696,IF(J45>0.7875,594.5418,IF(J45>0.77,2680.3206,346.4228))) -> 186.9696 | Q45: =IF(J45>0.8385,0.4862,IF(J45>0.7875,0,IF(J45>0.77,-0.00336312,0.4388))) -> 0.4862 | R45: =IF(OR(J45>0.7876,J45=0.7876),(P45/O45^2)+(Q45/O45),IF(OR(J45>0.7701,J45=0.7701),(P45/O45^2)+Q45,(P45/O45^2)+(Q45/O45))) -> 0.00074030796 | S45: =ROUND(EXP(-R45*N45*(1+0.8*R45*N45)),4) -> 0.9452
A46: =A26 -> OVERFLOW | B46: VLSFO | C46: S 00,16 | D46: 40 | E46: 0.3 | F46: Nil | G46: 0 | H46: =IF(E46="","",E46-G46) -> 0.3 | I46: =IF(E46="","",S46) -> 0.9814 | J46: 0.9287 | K46: =IF(E46="","",H46*I46) -> 0.29442 | L46: =IF(A46="","",ROUND(SUM(K46*J46),3)) -> 0.273 | M46: =(J46-0.0011)*K46 -> 0.27310399 | N46: =D46-15 -> 25 | O46: =J46*1000 -> 928.7 | P46: =IF(J46>0.8385,186.9696,IF(J46>0.7875,594.5418,IF(J46>0.77,2680.3206,346.4228))) -> 186.9696 | Q46: =IF(J46>0.8385,0.4862,IF(J46>0.7875,0,IF(J46>0.77,-0.00336312,0.4388))) -> 0.4862 | R46: =IF(OR(J46>0.7876,J46=0.7876),(P46/O46^2)+(Q46/O46),IF(OR(J46>0.7701,J46=0.7701),(P46/O46^2)+Q46,(P46/O46^2)+(Q46/O46))) -> 0.00074030796 | S46: =ROUND(EXP(-R46*N46*(1+0.8*R46*N46)),4) -> 0.9814
A47: =A27 -> 7 | B47: VLSFO | C47: 0 | D47: 0 | E47: 0 | F47: Nil | G47: 0 | H47: =IF(E47="","",E47-G47) -> 0 | I47: =IF(E47="","",S47) -> 1.0115 | J47: =J27 -> 0.9 | K47: =IF(E47="","",H47*I47) -> 0 | L47: =IF(A47="","",ROUND(SUM(K47*J47),3)) -> 0 | M47: =(J47-0.0011)*K47 -> 0 | N47: =D47-15 -> -15 | O47: =J47*1000 -> 900 | P47: =IF(J47>0.8385,186.9696,IF(J47>0.7875,594.5418,IF(J47>0.77,2680.3206,346.4228))) -> 186.9696 | Q47: =IF(J47>0.8385,0.4862,IF(J47>0.7875,0,IF(J47>0.77,-0.00336312,0.4388))) -> 0.4862 | R47: =IF(OR(J47>0.7876,J47=0.7876),(P47/O47^2)+(Q47/O47),IF(OR(J47>0.7701,J47=0.7701),(P47/O47^2)+Q47,(P47/O47^2)+(Q47/O47))) -> 0.00077104889 | S47: =ROUND(EXP(-R47*N47*(1+0.8*R47*N47)),4) -> 1.0115
A48: =A28 -> 8 | B48: VLSFO | C48: 0 | D48: 0 | E48: 0 | F48: Nil | G48: 0 | H48: =IF(E48="","",E48-G48) -> 0 | I48: =IF(E48="","",S48) -> 1.0115 | J48: =J28 -> 0.9 | K48: =IF(E48="","",H48*I48) -> 0 | L48: =IF(A48="","",ROUND(SUM(K48*J48),3)) -> 0 | M48: =(J48-0.0011)*K48 -> 0 | N48: =D48-15 -> -15 | O48: =J48*1000 -> 900 | P48: =IF(J48>0.8385,186.9696,IF(J48>0.7875,594.5418,IF(J48>0.77,2680.3206,346.4228))) -> 186.9696 | Q48: =IF(J48>0.8385,0.4862,IF(J48>0.7875,0,IF(J48>0.77,-0.00336312,0.4388))) -> 0.4862 | R48: =IF(OR(J48>0.7876,J48=0.7876),(P48/O48^2)+(Q48/O48),IF(OR(J48>0.7701,J48=0.7701),(P48/O48^2)+Q48,(P48/O48^2)+(Q48/O48))) -> 0.00077104889 | S48: =ROUND(EXP(-R48*N48*(1+0.8*R48*N48)),4) -> 1.0115
A49: =A29 -> 9 | B49: VLSFO | C49: 0 | D49: 0 | E49: 0 | F49: Nil | G49: 0 | H49: =IF(E49="","",E49-G49) -> 0 | I49: =IF(E49="","",S49) -> 1.0115 | J49: =J29 -> 0.9 | K49: =IF(E49="","",H49*I49) -> 0 | L49: =IF(A49="","",ROUND(SUM(K49*J49),3)) -> 0 | M49: =(J49-0.0011)*K49 -> 0 | N49: =D49-15 -> -15 | O49: =J49*1000 -> 900 | P49: =IF(J49>0.8385,186.9696,IF(J49>0.7875,594.5418,IF(J49>0.77,2680.3206,346.4228))) -> 186.9696 | Q49: =IF(J49>0.8385,0.4862,IF(J49>0.7875,0,IF(J49>0.77,-0.00336312,0.4388))) -> 0.4862 | R49: =IF(OR(J49>0.7876,J49=0.7876),(P49/O49^2)+(Q49/O49),IF(OR(J49>0.7701,J49=0.7701),(P49/O49^2)+Q49,(P49/O49^2)+(Q49/O49))) -> 0.00077104889 | S49: =ROUND(EXP(-R49*N49*(1+0.8*R49*N49)),4) -> 1.0115
A50: =A30 -> 10 | B50: VLSFO | C50: 0 | D50: 0 | E50: 0 | F50: Nil | G50: 0 | H50: =IF(E50="","",E50-G50) -> 0 | I50: =IF(E50="","",S50) -> 1.0115 | J50: =J30 -> 0.9 | K50: =IF(E50="","",H50*I50) -> 0 | L50: =IF(A50="","",ROUND(SUM(K50*J50),3)) -> 0 | M50: =(J50-0.0011)*K50 -> 0 | N50: =D50-15 -> -15 | O50: =J50*1000 -> 900 | P50: =IF(J50>0.8385,186.9696,IF(J50>0.7875,594.5418,IF(J50>0.77,2680.3206,346.4228))) -> 186.9696 | Q50: =IF(J50>0.8385,0.4862,IF(J50>0.7875,0,IF(J50>0.77,-0.00336312,0.4388))) -> 0.4862 | R50: =IF(OR(J50>0.7876,J50=0.7876),(P50/O50^2)+(Q50/O50),IF(OR(J50>0.7701,J50=0.7701),(P50/O50^2)+Q50,(P50/O50^2)+(Q50/O50))) -> 0.00077104889 | S50: =ROUND(EXP(-R50*N50*(1+0.8*R50*N50)),4) -> 1.0115
...

Sheet Sounding Barge
H2: MARINE SURVEYORS & CONSULTANTS
I3: Av. Ana Costa, 433 suite 184 - Santos /BR
H4: surveyors@naabsa.com | Naabsa.com | TEL: 55 13 3394-0655
B7: BARGE´S SOUNDING/ULLAGE REPORT
B9: Name of Vessel: | D9: ='Vessel Ullage'!C8 -> Elite Star | H9: Grade of Fuel Ordered: | J9: ='Vessel Ullage'!I8 -> VLSFO
H10: Location of Survey: | J10: ='Vessel Ullage'!I9 -> Santos Port - Tiplam Terminal
B11: Name of Barges : | D11: ='Vessel Ullage'!C10 -> SC 60 | H11: ='Vessel Ullage'!G10 -> Survey Start: | J11: ='Vessel Ullage'!I10 -> February 19th, 2026 - 08:00 lt
H12: ='Vessel Ullage'!G11 -> Survey Completed: | J12: ='Vessel Ullage'!I11 -> February 19th, 2026 - 21:00h lt
B16: BEFORE TRANSFER | J16: FLOWMETER | K16: N/A | N16: m3
B17: Draft Fore: | C17: 4.15 | D17: m | E17: Draft Aft: | F17: 4.15 | G17: m | H17: List: | I17: 0 | J17: Trim Correction Applied: | L17: YES | M17: METRIC TONS
B18: Tank nº | C18: Grade | D18: Sounding / Ullage (m) | E18: Deg C | F18: Total Vol Observed (m3) | G18: Free Water | I18: Gross Obs Vol (m3) | J18: VCF TAB 54B | K18: Density (S.G.) at 15° C | L18: Gross Std Vol @15° C | M18: IN VAC | N18: IN AIR
G19: Dip | H19: Vol
B20: 1 BB | C20: VLSFO | D20: 1.65 | E20: 46 | F20: 336.566 | G20: Nil | H20: 0 | I20: =IF(F20="","",F20-H20) -> 336.566 | J20: =IF(F20="","",T20) -> 0.9773 | K20: 0.941 | L20: =IF(F20="","",I20*J20) -> 328.92595 | M20: =IF(B20="","",ROUND(SUM(L20*K20),3)) -> 309.519 | N20: =(K20-0.0011)*L20 -> 309.1575 | O20: =IF(E20="","",E20-15) -> 31 | P20: =K20*1000 -> 941 | Q20: =IF(K20>0.8385,186.9696,IF(K20>0.7875,594.5418,IF(K20>0.77,2680.3206,346.4228))) -> 186.9696 | R20: =IF(K20>0.8385,0.4862,IF(K20>0.7875,0,IF(K20>0.77,-0.00336312,0.4388))) -> 0.4862 | S20: =IF(OR(K20>0.7876,K20=0.7876),(Q20/P20^2)+(R20/P20),IF(OR(K20>0.7701,K20=0.7701),(Q20/P20^2)+R20,(Q20/P20^2)+(R20/P20))) -> 0.0007278347 | T20: =ROUND(EXP(-S20*O20*(1+0.8*S20*O20)),4) -> 0.9773
B21: 1 BE | C21: VLSFO | D21: 1.685 | E21: 46 | F21: 333.956 | G21: Nil | H21: 0 | I21: =IF(F21="","",F21-H21) -> 333.956 | J21: =IF(F21="","",T21) -> 0.9773 | K21: 0.941 | L21: =IF(F21="","",I21*J21) -> 326.3752 | M21: =IF(B21="","",ROUND(SUM(L21*K21),3)) -> 307.119 | N21: =(K21-0.0011)*L21 -> 306.76005 | O21: =E21-15 -> 31 | P21: =K21*1000 -> 941 | Q21: =IF(K21>0.8385,186.9696,IF(K21>0.7875,594.5418,IF(K21>0.77,2680.3206,346.4228))) -> 186.9696 | R21: =IF(K21>0.8385,0.4862,IF(K21>0.7875,0,IF(K21>0.77,-0.00336312,0.4388))) -> 0.4862 | S21: =IF(OR(K21>0.7876,K21=0.7876),(Q21/P21^2)+(R21/P21),IF(OR(K21>0.7701,K21=0.7701),(Q21/P21^2)+R21,(Q21/P21^2)+(R21/P21))) -> 0.0007278347 | T21: =ROUND(EXP(-S21*O21*(1+0.8*S21*O21)),4) -> 0.9773
B22: 2 BB | C22: VLSFO | D22: 1.692 | E22: 46.5 | F22: 406.427 | G22: Nil | H22: 0 | I22: =IF(F22="","",F22-H22) -> 406.427 | J22: =IF(F22="","",T22) -> 0.9769 | K22: 0.941 | L22: =IF(F22="","",I22*J22) -> 397.03854 | M22: =IF(B22="","",ROUND(SUM(L22*K22),3)) -> 373.613 | N22: =(K22-0.0011)*L22 -> 373.17652 | O22: =E22-15 -> 31.5 | P22: =K22*1000 -> 941 | Q22: =IF(K22>0.8385,186.9696,IF(K22>0.7875,594.5418,IF(K22>0.77,2680.3206,346.4228))) -> 186.9696 | R22: =IF(K22>0.8385,0.4862,IF(K22>0.7875,0,IF(K22>0.77,-0.00336312,0.4388))) -> 0.4862 | S22: =IF(OR(K22>0.7876,K22=0.7876),(Q22/P22^2)+(R22/P22),IF(OR(K22>0.7701,K22=0.7701),(Q22/P22^2)+R22,(Q22/P22^2)+(R22/P22))) -> 0.0007278347 | T22: =ROUND(EXP(-S22*O22*(1+0.8*S22*O22)),4) -> 0.9769
B23: 2 BE | C23: VLSFO | D23: 1.7 | E23: 46.5 | F23: 403.101 | G23: Nil | H23: 0 | I23: =IF(F23="","",F23-H23) -> 403.101 | J23: =IF(F23="","",T23) -> 0.9769 | K23: 0.941 | L23: =IF(F23="","",I23*J23) -> 393.78937 | M23: =IF(B23="","",ROUND(SUM(L23*K23),3)) -> 370.556 | N23: =(K23-0.0011)*L23 -> 370.12263 | O23: =E23-15 -> 31.5 | P23: =K23*1000 -> 941 | Q23: =IF(K23>0.8385,186.9696,IF(K23>0.7875,594.5418,IF(K23>0.77,2680.3206,346.4228))) -> 186.9696 | R23: =IF(K23>0.8385,0.4862,IF(K23>0.7875,0,IF(K23>0.77,-0.00336312,0.4388))) -> 0.4862 | S23: =IF(OR(K23>0.7876,K23=0.7876),(Q23/P23^2)+(R23/P23),IF(OR(K23>0.7701,K23=0.7701),(Q23/P23^2)+R23,(Q23/P23^2)+(R23/P23))) -> 0.0007278347 | T23: =ROUND(EXP(-S23*O23*(1+0.8*S23*O23)),4) -> 0.9769
B24: 3 BB | C24: VLSFO | D24: 1.431 | E24: 46.5 | F24: 431.796 | G24: Nil | H24: 0 | I24: =IF(F24="","",F24-H24) -> 431.796 | J24: =IF(F24="","",T24) -> 0.9769 | K24: 0.941 | L24: =IF(F24="","",I24*J24) -> 421.82151 | M24: =IF(B24="","",ROUND(SUM(L24*K24),3)) -> 396.934 | N24: =(K24-0.0011)*L24 -> 396.47004 | O24: =E24-15 -> 31.5 | P24: =K24*1000 -> 941 | Q24: =IF(K24>0.8385,186.9696,IF(K24>0.7875,594.5418,IF(K24>0.77,2680.3206,346.4228))) -> 186.9696 | R24: =IF(K24>0.8385,0.4862,IF(K24>0.7875,0,IF(K24>0.77,-0.00336312,0.4388))) -> 0.4862 | S24: =IF(OR(K24>0.7876,K24=0.7876),(Q24/P24^2)+(R24/P24),IF(OR(K24>0.7701,K24=0.7701),(Q24/P24^2)+R24,(Q24/P24^2)+(R24/P24))) -> 0.0007278347 | T24: =ROUND(EXP(-S24*O24*(1+0.8*S24*O24)),4) -> 0.9769
B25: 3 BE | C25: VLSFO | D25: 1.472 | E25: 46 | F25: 426.684 | G25: Nil | H25: 0 | I25: =IF(F25="","",F25-H25) -> 426.684 | J25: =IF(F25="","",T25) -> 0.9773 | K25: 0.941 | L25: =IF(F25="","",I25*J25) -> 416.99827 | M25: =IF(B25="","",ROUND(SUM(L25*K25),3)) -> 392.395 | N25: =(K25-0.0011)*L25 -> 391.93668 | O25: =E25-15 -> 31 | P25: =K25*1000 -> 941 | Q25: =IF(K25>0.8385,186.9696,IF(K25>0.7875,594.5418,IF(K25>0.77,2680.3206,346.4228))) -> 186.9696 | R25: =IF(K25>0.8385,0.4862,IF(K25>0.7875,0,IF(K25>0.77,-0.00336312,0.4388))) -> 0.4862 | S25: =IF(OR(K25>0.7876,K25=0.7876),(Q25/P25^2)+(R25/P25),IF(OR(K25>0.7701,K25=0.7701),(Q25/P25^2)+R25,(Q25/P25^2)+(R25/P25))) -> 0.0007278347 | T25: =ROUND(EXP(-S25*O25*(1+0.8*S25*O25)),4) -> 0.9773
B26: 4 BB | C26: VLSFO | D26: 1.696 | E26: 47 | F26: 406.844 | G26: Nil | H26: 0 | I26: =IF(F26="","",F26-H26) -> 406.844 | J26: =IF(F26="","",T26) -> 0.9766 | K26: 0.941 | L26: =IF(F26="","",I26*J26) -> 397.32385 | M26: =IF(B26="","",ROUND(SUM(L26*K26),3)) -> 373.882 | N26: =(K26-0.0011)*L26 -> 373.44469 | O26: =E26-15 -> 32 | P26: =K26*1000 -> 941 | Q26: =IF(K26>0.8385,186.9696,IF(K26>0.7875,594.5418,IF(K26>0.77,2680.3206,346.4228))) -> 186.9696 | R26: =IF(K26>0.8385,0.4862,IF(K26>0.7875,0,IF(K26>0.77,-0.00336312,0.4388))) -> 0.4862 | S26: =IF(OR(K26>0.7876,K26=0.7876),(Q26/P26^2)+(R26/P26),IF(OR(K26>0.7701,K26=0.7701),(Q26/P26^2)+R26,(Q26/P26^2)+(R26/P26))) -> 0.0007278347 | T26: =ROUND(EXP(-S26*O26*(1+0.8*S26*O26)),4) -> 0.9766
B27: 4 BE | C27: VLSFO | D27: 1.696 | E27: 46.5 | F27: 406.693 | G27: Nil | H27: 0 | I27: =IF(F27="","",F27-H27) -> 406.693 | J27: =IF(F27="","",T27) -> 0.9769 | K27: 0.941 | L27: =IF(F27="","",I27*J27) -> 397.29839 | M27: =IF(B27="","",ROUND(SUM(L27*K27),3)) -> 373.858 | N27: =(K27-0.0011)*L27 -> 373.42076 | O27: =E27-15 -> 31.5 | P27: =K27*1000 -> 941 | Q27: =IF(K27>0.8385,186.9696,IF(K27>0.7875,594.5418,IF(K27>0.77,2680.3206,346.4228))) -> 186.9696 | R27: =IF(K27>0.8385,0.4862,IF(K27>0.7875,0,IF(K27>0.77,-0.00336312,0.4388))) -> 0.4862 | S27: =IF(OR(K27>0.7876,K27=0.7876),(Q27/P27^2)+(R27/P27),IF(OR(K27>0.7701,K27=0.7701),(Q27/P27^2)+R27,(Q27/P27^2)+(R27/P27))) -> 0.0007278347 | T27: =ROUND(EXP(-S27*O27*(1+0.8*S27*O27)),4) -> 0.9769
B28: 5 BB | C28: VLSFO | D28: 1.645 | E28: 46 | F28: 363.199 | G28: Nil | H28: 0 | I28: =IF(F28="","",F28-H28) -> 363.199 | J28: =IF(F28="","",T28) -> 0.9773 | K28: 0.941 | L28: =IF(F28="","",I28*J28) -> 354.95438 | M28: =IF(B28="","",ROUND(SUM(L28*K28),3)) -> 334.012 | N28: =(K28-0.0011)*L28 -> 333.62162 | O28: =E28-15 -> 31 | P28: =K28*1000 -> 941 | Q28: =IF(K28>0.8385,186.9696,IF(K28>0.7875,594.5418,IF(K28>0.77,2680.3206,346.4228))) -> 186.9696 | R28: =IF(K28>0.8385,0.4862,IF(K28>0.7875,0,IF(K28>0.77,-0.00336312,0.4388))) -> 0.4862 | S28: =IF(OR(K28>0.7876,K28=0.7876),(Q28/P28^2)+(R28/P28),IF(OR(K28>0.7701,K28=0.7701),(Q28/P28^2)+R28,(Q28/P28^2)+(R28/P28))) -> 0.0007278347 | T28: =ROUND(EXP(-S28*O28*(1+0.8*S28*O28)),4) -> 0.9773
B29: 5 BE | C29: VLSFO | D29: 1.642 | E29: 46.5 | F29: 364.115 | G29: Nil | H29: 0 | I29: =IF(F29="","",F29-H29) -> 364.115 | J29: =IF(F29="","",T29) -> 0.9769 | K29: 0.941 | L29: =IF(F29="","",I29*J29) -> 355.70394 | M29: =IF(B29="","",ROUND(SUM(L29*K29),3)) -> 334.717 | N29: =(K29-0.0011)*L29 -> 334.32614 | O29: =E29-15 -> 31.5 | P29: =K29*1000 -> 941 | Q29: =IF(K29>0.8385,186.9696,IF(K29>0.7875,594.5418,IF(K29>0.77,2680.3206,346.4228))) -> 186.9696 | R29: =IF(K29>0.8385,0.4862,IF(K29>0.7875,0,IF(K29>0.77,-0.00336312,0.4388))) -> 0.4862 | S29: =IF(OR(K29>0.7876,K29=0.7876),(Q29/P29^2)+(R29/P29),IF(OR(K29>0.7701,K29=0.7701),(Q29/P29^2)+R29,(Q29/P29^2)+(R29/P29))) -> 0.0007278347 | T29: =ROUND(EXP(-S29*O29*(1+0.8*S29*O29)),4) -> 0.9769
F30: Total | I30: =SUM(I20:I29) -> 3879.381 | J30: =MEDIAN(J20:J29) -> 0.9769 | K30: =MEDIAN(K20:K29) -> 0.941 | L30: =SUM(L20:L29) -> 3790.2294 | M30: =ROUND(SUM(M20:M29),3) -> 3566.605 | N30: =SUM(N20:N29) -> 3562.4366
B33: AFTER RECEIVING | J33: FLOWMETER | K33: N/A | N33: m3
B34: Draft Fore: | C34: 3.4 | D34: m | E34: Draft Aft: | F34: 3.4 | G34: m | H34: List: | I34: 0 | J34: Trim Correction Applied: | L34: YES | M34: METRIC TONS
B35: Tank nº | C35: Grade | D35: Sounding / Ullage (m) | E35: Deg C | F35: Total Vol Observed (m3) | G35: Free Water | I35: Gross Obs Vol (m3) | J35: VCF TAB 54B | K35: Density (S.G.) at 15° C | L35: Gross Std Vol @15° C | M35: IN VAC | N35: IN AIR
G36: Dip | H36: Vol | X36: =SUM(L20:L29) -> 3790.2294
B37: =B20 -> 1 BB | C37: =C20 -> VLSFO | D37: 4.42 | E37: 44.5 | F37: 94.232 | G37: Nil | H37: 0 | I37: =IF(F37="","",F37-H37) -> 94.232 | J37: =IF(F37="","",T37) -> 0.9784 | K37: =K20 -> 0.941 | L37: =IF(F37="","",I37*J37) -> 92.196589 | M37: =IF(B37="","",ROUND(SUM(L37*K37),3)) -> 86.757 | N37: =(K37-0.0011)*L37 -> 86.655574 | O37: =IF(E37="","",E37-15) -> 29.5 | P37: =K37*1000 -> 941 | Q37: =IF(K37>0.8385,186.9696,IF(K37>0.7875,594.5418,IF(K37>0.77,2680.3206,346.4228))) -> 186.9696 | R37: =IF(K37>0.8385,0.4862,IF(K37>0.7875,0,IF(K37>0.77,-0.00336312,0.4388))) -> 0.4862 | S37: =IF(OR(K37>0.7876,K37=0.7876),(Q37/P37^2)+(R37/P37),IF(OR(K37>0.7701,K37=0.7701),(Q37/P37^2)+R37,(Q37/P37^2)+(R37/P37))) -> 0.0007278347 | T37: =ROUND(EXP(-S37*O37*(1+0.8*S37*O37)),4) -> 0.9784 | W37: =I30-I47 -> 978.374 | X37: =SUM(L37:L46) -> 2835.0277 | Y37: =624.8*0.9799 -> 612.24152
B38: =B21 -> 1 BE | C38: =C21 -> VLSFO | D38: 4.417 | E38: 44.5 | F38: 95.427 | G38: Nil | H38: 0 | I38: =IF(F38="","",F38-H38) -> 95.427 | J38: =IF(F38="","",T38) -> 0.9784 | K38: =K21 -> 0.941 | L38: =IF(F38="","",I38*J38) -> 93.365777 | M38: =IF(B38="","",ROUND(SUM(L38*K38),3)) -> 87.857 | N38: =(K38-0.0011)*L38 -> 87.754494 | O38: =E38-15 -> 29.5 | P38: =K38*1000 -> 941 | Q38: =IF(K38>0.8385,186.9696,IF(K38>0.7875,594.5418,IF(K38>0.77,2680.3206,346.4228))) -> 186.9696 | R38: =IF(K38>0.8385,0.4862,IF(K38>0.7875,0,IF(K38>0.77,-0.00336312,0.4388))) -> 0.4862 | S38: =IF(OR(K38>0.7876,K38=0.7876),(Q38/P38^2)+(R38/P38),IF(OR(K38>0.7701,K38=0.7701),(Q38/P38^2)+R38,(Q38/P38^2)+(R38/P38))) -> 0.0007278347 | T38: =ROUND(EXP(-S38*O38*(1+0.8*S38*O38)),4) -> 0.9784 | W38: =W37*0.9799 -> 958.70868 | X38: =X36-X37 -> 955.20167 | Y38: =Y37*0.9475 -> 580.09884
B39: =B22 -> 2 BB | C39: =C22 -> VLSFO | D39: 1.7 | E39: 46.5 | F39: 405.714 | G39: Nil | H39: 0 | I39: =IF(F39="","",F39-H39) -> 405.714 | J39: =IF(F39="","",T39) -> 0.9769 | K39: =K22 -> 0.941 | L39: =IF(F39="","",I39*J39) -> 396.34201 | M39: =IF(B39="","",ROUND(SUM(L39*K39),3)) -> 372.958 | N39: =(K39-0.0011)*L39 -> 372.52185 | O39: =E39-15 -> 31.5 | P39: =K39*1000 -> 941 | Q39: =IF(K39>0.8385,186.9696,IF(K39>0.7875,594.5418,IF(K39>0.77,2680.3206,346.4228))) -> 186.9696 | R39: =IF(K39>0.8385,0.4862,IF(K39>0.7875,0,IF(K39>0.77,-0.00336312,0.4388))) -> 0.4862 | S39: =IF(OR(K39>0.7876,K39=0.7876),(Q39/P39^2)+(R39/P39),IF(OR(K39>0.7701,K39=0.7701),(Q39/P39^2)+R39,(Q39/P39^2)+(R39/P39))) -> 0.0007278347 | T39: =ROUND(EXP(-S39*O39*(1+0.8*S39*O39)),4) -> 0.9769 | W39: =W38*0.9475 -> 908.37648
B40: =B23 -> 2 BE | C40: =C23 -> VLSFO | D40: 1.706 | E40: 46 | F40: 402.568 | G40: Nil | H40: 0 | I40: =IF(F40="","",F40-H40) -> 402.568 | J40: =IF(F40="","",T40) -> 0.9773 | K40: =K23 -> 0.941 | L40: =IF(F40="","",I40*J40) -> 393.42971 | M40: =IF(B40="","",ROUND(SUM(L40*K40),3)) -> 370.217 | N40: =(K40-0.0011)*L40 -> 369.78458 | O40: =E40-15 -> 31 | P40: =K40*1000 -> 941 | Q40: =IF(K40>0.8385,186.9696,IF(K40>0.7875,594.5418,IF(K40>0.77,2680.3206,346.4228))) -> 186.9696 | R40: =IF(K40>0.8385,0.4862,IF(K40>0.7875,0,IF(K40>0.77,-0.00336312,0.4388))) -> 0.4862 | S40: =IF(OR(K40>0.7876,K40=0.7876),(Q40/P40^2)+(R40/P40),IF(OR(K40>0.7701,K40=0.7701),(Q40/P40^2)+R40,(Q40/P40^2)+(R40/P40))) -> 0.0007278347 | T40: =ROUND(EXP(-S40*O40*(1+0.8*S40*O40)),4) -> 0.9773
B41: =B24 -> 3 BB | C41: =C24 -> VLSFO | D41: 1.429 | E41: 46.5 | F41: 431.975 | G41: Nil | H41: 0 | I41: =IF(F41="","",F41-H41) -> 431.975 | J41: =IF(F41="","",T41) -> 0.9769 | K41: =K24 -> 0.941 | L41: =IF(F41="","",I41*J41) -> 421.99638 | M41: =IF(B41="","",ROUND(SUM(L41*K41),3)) -> 397.099 | N41: =(K41-0.0011)*L41 -> 396.6344 | O41: =E41-15 -> 31.5 | P41: =K41*1000 -> 941 | Q41: =IF(K41>0.8385,186.9696,IF(K41>0.7875,594.5418,IF(K41>0.77,2680.3206,346.4228))) -> 186.9696 | R41: =IF(K41>0.8385,0.4862,IF(K41>0.7875,0,IF(K41>0.77,-0.00336312,0.4388))) -> 0.4862 | S41: =IF(OR(K41>0.7876,K41=0.7876),(Q41/P41^2)+(R41/P41),IF(OR(K41>0.7701,K41=0.7701),(Q41/P41^2)+R41,(Q41/P41^2)+(R41/P41))) -> 0.0007278347 | T41: =ROUND(EXP(-S41*O41*(1+0.8*S41*O41)),4) -> 0.9769
B42: =B25 -> 3 BE | C42: =C25 -> VLSFO | D42: 1.474 | E42: 46 | F42: 426.506 | G42: Nil | H42: 0 | I42: =IF(F42="","",F42-H42) -> 426.506 | J42: =IF(F42="","",T42) -> 0.9773 | K42: =K25 -> 0.941 | L42: =IF(F42="","",I42*J42) -> 416.82431 | M42: =IF(B42="","",ROUND(SUM(L42*K42),3)) -> 392.232 | N42: =(K42-0.0011)*L42 -> 391.77317 | O42: =E42-15 -> 31 | P42: =K42*1000 -> 941 | Q42: =IF(K42>0.8385,186.9696,IF(K42>0.7875,594.5418,IF(K42>0.77,2680.3206,346.4228))) -> 186.9696 | R42: =IF(K42>0.8385,0.4862,IF(K42>0.7875,0,IF(K42>0.77,-0.00336312,0.4388))) -> 0.4862 | S42: =IF(OR(K42>0.7876,K42=0.7876),(Q42/P42^2)+(R42/P42),IF(OR(K42>0.7701,K42=0.7701),(Q42/P42^2)+R42,(Q42/P42^2)+(R42/P42))) -> 0.0007278347 | T42: =ROUND(EXP(-S42*O42*(1+0.8*S42*O42)),4) -> 0.9773
B43: =B26 -> 4 BB | C43: =C26 -> VLSFO | D43: 1.701 | E43: 46.5 | F43: 406.399 | G43: Nil | H43: 0 | I43: =IF(F43="","",F43-H43) -> 406.399 | J43: =IF(F43="","",T43) -> 0.9769 | K43: =K26 -> 0.941 | L43: =IF(F43="","",I43*J43) -> 397.01118 | M43: =IF(B43="","",ROUND(SUM(L43*K43),3)) -> 373.588 | N43: =(K43-0.0011)*L43 -> 373.15081 | O43: =E43-15 -> 31.5 | P43: =K43*1000 -> 941 | Q43: =IF(K43>0.8385,186.9696,IF(K43>0.7875,594.5418,IF(K43>0.77,2680.3206,346.4228))) -> 186.9696 | R43: =IF(K43>0.8385,0.4862,IF(K43>0.7875,0,IF(K43>0.77,-0.00336312,0.4388))) -> 0.4862 | S43: =IF(OR(K43>0.7876,K43=0.7876),(Q43/P43^2)+(R43/P43),IF(OR(K43>0.7701,K43=0.7701),(Q43/P43^2)+R43,(Q43/P43^2)+(R43/P43))) -> 0.0007278347 | T43: =ROUND(EXP(-S43*O43*(1+0.8*S43*O43)),4) -> 0.9769
B44: =B27 -> 4 BE | C44: =C27 -> VLSFO | D44: 1.705 | E44: 46 | F44: 405.892 | G44: Nil | H44: 0 | I44: =IF(F44="","",F44-H44) -> 405.892 | J44: =IF(F44="","",T44) -> 0.9773 | K44: =K27 -> 0.941 | L44: =IF(F44="","",I44*J44) -> 396.67825 | M44: =IF(B44="","",ROUND(SUM(L44*K44),3)) -> 373.274 | N44: =(K44-0.0011)*L44 -> 372.83789 | O44: =E44-15 -> 31 | P44: =K44*1000 -> 941 | Q44: =IF(K44>0.8385,186.9696,IF(K44>0.7875,594.5418,IF(K44>0.77,2680.3206,346.4228))) -> 186.9696 | R44: =IF(K44>0.8385,0.4862,IF(K44>0.7875,0,IF(K44>0.77,-0.00336312,0.4388))) -> 0.4862 | S44: =IF(OR(K44>0.7876,K44=0.7876),(Q44/P44^2)+(R44/P44),IF(OR(K44>0.7701,K44=0.7701),(Q44/P44^2)+R44,(Q44/P44^2)+(R44/P44))) -> 0.0007278347 | T44: =ROUND(EXP(-S44*O44*(1+0.8*S44*O44)),4) -> 0.9773
B45: =B28 -> 5 BB | C45: =C28 -> VLSFO | D45: 4.425 | E45: 45 | F45: 115.73 | G45: Nil | H45: 0 | I45: =IF(F45="","",F45-H45) -> 115.73 | J45: =IF(F45="","",T45) -> 0.978 | K45: =K28 -> 0.941 | L45: =IF(F45="","",I45*J45) -> 113.18394 | M45: =IF(B45="","",ROUND(SUM(L45*K45),3)) -> 106.506 | N45: =(K45-0.0011)*L45 -> 106.38159 | O45: =E45-15 -> 30 | P45: =K45*1000 -> 941 | Q45: =IF(K45>0.8385,186.9696,IF(K45>0.7875,594.5418,IF(K45>0.77,2680.3206,346.4228))) -> 186.9696 | R45: =IF(K45>0.8385,0.4862,IF(K45>0.7875,0,IF(K45>0.77,-0.00336312,0.4388))) -> 0.4862 | S45: =IF(OR(K45>0.7876,K45=0.7876),(Q45/P45^2)+(R45/P45),IF(OR(K45>0.7701,K45=0.7701),(Q45/P45^2)+R45,(Q45/P45^2)+(R45/P45))) -> 0.0007278347 | T45: =ROUND(EXP(-S45*O45*(1+0.8*S45*O45)),4) -> 0.978
B46: =B29 -> 5 BE | C46: =C29 -> VLSFO | D46: 4.42 | E46: 45 | F46: 116.564 | G46: Nil | H46: 0 | I46: =IF(F46="","",F46-H46) -> 116.564 | J46: =IF(F46="","",T46) -> 0.978 | K46: =K29 -> 0.941 | L46: =IF(F46="","",I46*J46) -> 113.99959 | M46: =IF(B46="","",ROUND(SUM(L46*K46),3)) -> 107.274 | N46: =(K46-0.0011)*L46 -> 107.14822 | O46: =E46-15 -> 30 | P46: =K46*1000 -> 941 | Q46: =IF(K46>0.8385,186.9696,IF(K46>0.7875,594.5418,IF(K46>0.77,2680.3206,346.4228))) -> 186.9696 | R46: =IF(K46>0.8385,0.4862,IF(K46>0.7875,0,IF(K46>0.77,-0.00336312,0.4388))) -> 0.4862 | S46: =IF(OR(K46>0.7876,K46=0.7876),(Q46/P46^2)+(R46/P46),IF(OR(K46>0.7701,K46=0.7701),(Q46/P46^2)+R46,(Q46/P46^2)+(R46/P46))) -> 0.0007278347 | T46: =ROUND(EXP(-S46*O46*(1+0.8*S46*O46)),4) -> 0.978
F47: Total | I47: =SUM(I37:I46) -> 2901.007 | J47: =MEDIAN(J37:J46) -> 0.9773 | K47: =MEDIAN(K37:K46) -> 0.941 | L47: =SUM(L37:L46) -> 2835.0277 | M47: =ROUND(SUM(M37:M46),3) -> 2667.762 | N47: =SUM(N37:N46) -> 2664.6426
B49: Density @ 15 Deg C as per BDN - Bunker Deliver Notice | E49: Density @ 20 Deg C as per BDN - Bunker Deliver Notice | I49: TOTAL QTY TRANSFERRED - ULLAGE/SOUNDING | M49: =N30-N47 -> 897.79405 | N49: MT
B51: 0.941 | E51: 0.9377 | I51: TOTAL QTY TRANSFERRED - FLOWMETER | M51: N/A | N51: MT
...

Sheet Time Log
F2: MARINE SURVEYORS & CONSULTANTS
G3: Av. Ana Costa, 433 suite 184 - Santos /BR
F4: surveyors@naabsa.com | Naabsa.com | TEL: 55 13 3394-0655
A7: TIME LOG
A9: Name of Vessel: | C9: ='Vessel Ullage'!C8 -> Elite Star | E9: Grade of Fuel Ordered: | G9: ='Vessel Ullage'!I8 -> VLSFO
E10: Location of Survey: | G10: ='Vessel Ullage'!I9 -> Santos Port - Tiplam Terminal
A11: Name of Barges : | C11: ='Vessel Ullage'!C10 -> SC 60 | E11: ='Vessel Ullage'!G10 -> Survey Start: | G11: ='Vessel Ullage'!I10 -> February 19th, 2026 - 08:00 lt
E12: ='Vessel Ullage'!G11 -> Survey Completed: | G12: ='Vessel Ullage'!I11 -> February 19th, 2026 - 21:00h lt
A15: Operation | D15: Date | E15: Times
A16: POB for berthing | D16: 46072 | E16: 0.20833333
A17: Gangway down | D17: 46072 | E17: 0.33333333 | Y17: 21418555
A18: Surveyor onboard | D18: 46072 | E18: 0.33333333
A19: Meeting between C/E and surveyor | D19: 46072 | E19: 0.33680556 | F19: 0.34027778
A20: Initial Soundings/Ullage - Vessel | D20: 46072 | E20: 0.34375 | F20: 0.36111111
A21: Awaiting barge | D21: 46072 | E21: 0.36111111 | F21: 0.45833333
A22: Bunker Barge arrived | D22: 46072 | E22: 0.45833333
A23: All fast / Barge ready | D23: 46072 | E23: 0.48611111
A24: Initial Soundings/Ullage - Barge | D24: 46072 | E24: 0.53472222 | F24: 0.55208333
A25: Hose Connected | D25: 46072 | E25: 0.58333333
A26: Bunkering operation | D26: 46072 | E26: 0.59375 | F26: 0.77083333
A27: Final Soundings/Ullage - Barge | D27: 46072 | E27: 0.77777778 | F27: 0.79166667
A28: Final Soundings/Ullage - Vessel | D28: 46072 | E28: 19;10 | F28: 0.8125
A29: Calculation | D29: 46072 | E29: 0.81944444 | F29: 0.84375
A30: Documents signed | D30: 46072 | E30: 0.85416667
A31: Hose disconnected | D31: 46072 | E31: 0.86458333
A32: Surveyor off board | D32: 46072 | E32: 0.875
A35: Stoppages/Delays
A36: NO DELAYS
A45: Remark:
A56: CHIEF ENGINEER: | C56: ='Vessel Ullage'!D74 -> YEPING WU | G56: SURVEYOR: | I56: ='Vessel Ullage'!K74 -> ARTHUR ARANTES FELICIO

Sheet Sample Report
G2: MARINE SURVEYORS & CONSULTANTS
G3: Av. Ana Costa, 433 suite 184 - Santos /BR
F4: surveyors@naabsa.com | Naabsa.com | TEL: 55 13 3394-0655
A9: SAMPLE REPORT
A11: Name of Vessel: | C11: ='Vessel Ullage'!C8 -> Elite Star | E11: Grade of Fuel Ordered: | G11: ='Vessel Ullage'!I8 -> VLSFO
E12: Location of Survey: | G12: ='Vessel Ullage'!I9 -> Santos Port - Tiplam Terminal
A13: Name of Barges : | C13: ='Vessel Ullage'!C10 -> SC 60 | E13: ='Vessel Ullage'!G10 -> Survey Start: | G13: ='Vessel Ullage'!I10 -> February 19th, 2026 - 08:00 lt
E14: ='Vessel Ullage'!G11 -> Survey Completed: | G14: ='Vessel Ullage'!I11 -> February 19th, 2026 - 21:00h lt
A17: SAMPLES WERE TAKEN DURING BUNKERING
A19: Name of barge | D19: ='Vessel Ullage'!C10 -> SC 60
A20: Grade | D20: ='Vessel Ullage'!I8 -> VLSFO
A21: Tank number | D21: 1BB, 1BE, 5BB and 5BE
A22: Sampling Method | D22: DRIPPING
A23: Sampling Point | D23: SHIP MANIFOLD | F23: BARGE MANIFOLD
A24: Quantity of Sample | D24: 5 x 0,5 L | F24: 4 x 0,5 L
A25: SAMPLES | D25: VESSEL | F25: BARGE
A26: Retained by Chife Engineer | D26: 5237253 | F26: 0024482
A27: Retained by Supplier`s Representative | D27: 5242213 | F27: 0024483
A28: Laboratory | D28: 5239733 | F28: N/I
A29: Marpol Sample | D29: 8378121 | F29: 0024484
A30: Surveyor Samples | D30: 7375836 | F30: N/A
A33: Remarks(IF ANY)
A38: CHIEF ENGINEER: | C38: ='Vessel Ullage'!D74 -> YEPING WU | G38: SURVEYOR: | I38: ='Vessel Ullage'!K74 -> ARTHUR ARANTES FELICIO

Sheet Letter of Protest (2)
G2: MARINE SURVEYORS & CONSULTANTS
H3: Av. Ana Costa, 433 suite 184 - Santos /BR
G4: surveyors@naabsa.com | Naabsa.com | TEL: 55 13 3394-0655
A8: Name of Vessel: | C8: ='Vessel Ullage'!C8 -> Elite Star | F8: Grade of Fuel Ordered: | H8: ='Sounding Barge'!J9 -> VLSFO
F9: Location of Survey: | H9: ='Vessel Ullage'!I9 -> Santos Port - Tiplam Terminal
A10: Name of Barges : | C10: ='Vessel Ullage'!C10 -> SC 60 | F10: ='Vessel Ullage'!G10 -> Survey Start: | H10: ='Vessel Ullage'!I10 -> February 19th, 2026 - 08:00 lt
F11: ='Vessel Ullage'!G11 -> Survey Completed: | H11: ='Vessel Ullage'!I11 -> February 19th, 2026 - 21:00h lt
A13: To: Supplier or representative
A15: C/c: CHIEF ENGINEER
F18: LETTER OF PROTEST
A23: Vessel : | B23: ='Vessel Ullage'!C8 -> Elite Star | F23: Date :
A25: Location : | B25: ='Vessel Ullage'!I9 -> Santos Port - Tiplam Terminal | F25: Product : | G25: ='Vessel Ullage'!I8 -> VLSFO
A28: We have been appointed as Marine Surveyors to act on behalf of our Principals and the following
A29: figures is brought to your attention to the differences bellow:
F32: difference
D33: BDN | E33: NAABSA | F33: MT | G33: %
D34: ='Vessel Ullage'!L58 -> 900.022 | E34: ='Vessel Ullage'!L59 -> 900.14076 | F34: ='Vessel Ullage'!L60 -> 0.11875862 | G34: ='Vessel Ullage'!L61 -> 0.013195079
A36: We hereby reserve the right of our Principals to make reference to the above at a later date.
A43: Signed for receipt:
A45: VESSEL/BARGE REPRESENTATIVE : | G45: SURVEYOR: | I45: ='Vessel Ullage'!K74 -> ARTHUR ARANTES FELICIO
A46: STAMPED AND SIGNED

Sheet VacuoAr
A1: Density at 15C | B1: FCW Vacuo-Ar
A2: 0.5 | B2: 0.99775
A3: 0.5191 | B3: 0.99775
A4: 0.5192 | B4: 0.99785
A5: 0.5421 | B5: 0.99785
A6: 0.5422 | B6: 0.99795
A7: 0.5673 | B7: 0.99795
A8: 0.5674 | B8: 0.99805
A9: 0.595 | B9: 0.99805
A10: 0.5951 | B10: 0.99815
A11: 0.6255 | B11: 0.99815
A12: 0.6256 | B12: 0.99825
A13: 0.6593 | B13: 0.99825
... A29: 1.1 | B29: 0.99905
